Workbook

Sheet Promo Form
A1: AUSTRALIAN Claim Number | D1: Name of Promotion. | F1: Rebate | G1: 6 | S1: Rebate | T1: 6 | AF1: Rebate | AG1: 6 | AS1: Rebate | AT1: 6 | BF1: Rebate | BG1: 6 | BS1: Rebate | BT1: 6 | CF1: Rebate | CG1: 6
A2: Brand | F2: =_xlfn.XLOOKUP(F$3,'Data Validation'!$A:$A,'Data Validation'!$B:$B) -> 0.135 | N2: Growth Expectation | O2: 0.2 | S2: =_xlfn.XLOOKUP(S$3,'Data Validation'!$A:$A,'Data Validation'!$B:$B) -> 0.19 | AA2: Growth Expectation | AB2: 0.2 | AF2: =_xlfn.XLOOKUP(AF$3,'Data Validation'!$A:$A,'Data Validation'!$B:$B) -> 0.125 | AN2: Growth Expectation | AO2: 0.2 | AS2: =_xlfn.XLOOKUP(AS$3,'Data Validation'!$A:$A,'Data Validation'!$B:$B) -> 0.15 | BA2: Growth Expectation | BB2: 0.2 | BF2: =_xlfn.XLOOKUP(BF$3,'Data Validation'!$A:$A,'Data Validation'!$B:$B) -> 0.2 | BN2: Growth Expectation | BO2: 0.2 | BS2: =_xlfn.XLOOKUP(BS$3,'Data Validation'!$A:$A,'Data Validation'!$B:$B) -> 0.17 | CA2: Growth Expectation | CB2: 0.2 | CF2: =_xlfn.XLOOKUP(CF$3,'Data Validation'!$A:$A,'Data Validation'!$B:$B) -> 0.17 | CN2: Growth Expectation | CO2: 0.2
A3: Promo Date(s) | B3: =(B5-A5+1)/7 -> 2 | C3: Code | D3: Product Description | F3: AU - Officeworks | G3: <-- Select | J3: =F3 -> AU - Officeworks | S3: JB HIFI | T3: <-- Select | W3: =S3 -> JB HIFI | AF3: AU - Amazon | AG3: <-- Select | AJ3: =AF3 -> AU - Amazon | AS3: AU - The Good Guys | AT3: <-- Select | AW3: =AS3 -> AU - The Good Guys | BF3: Bing Lee | BG3: <-- Select | BJ3: =BF3 -> Bing Lee | BS3: Harvey Norman | BT3: <-- Select | BW3: =BS3 -> Harvey Norman | CF3: Harvey Norman | CG3: <-- Select | CJ3: =CF3 -> Harvey Norman
A4: From | B4: To | F4: Customer Code | G4: Retailer Buy ex | H4: Supplier Support | I4: MG Support | J4: Total Support | K4: End to End Standard Margin | L4: End to End Promo Margin | M4: Customer SOH | N4: Customer 6wk Avg | O4: Expected Sales / Actual Sales | P4: Supplier Claim Amount | Q4: MacGear Claim Amount | S4: Customer Code | T4: Retailer Buy ex | U4: Supplier Support | V4: MG Support | W4: Total Support | X4: End to End Standard Margin | Y4: End to End Promo Margin | Z4: Customer SOH | AA4: Customer 6wk Avg | AB4: Expected Sales / Actual Sales | AC4: Supplier Claim Amount | AD4: MacGear Claim Amount | AF4: Customer Code | AG4: Retailer Buy ex | AH4: Supplier Support | AI4: MG Support | AJ4: Total Support | AK4: End to End Standard Margin | AL4: End to End Promo Margin | AM4: Customer SOH | AN4: Customer 6wk Avg | AO4: Expected Sales / Actual Sales | AP4: Supplier Claim Amount | AQ4: MacGear Claim Amount | AS4: Customer Code | AT4: Retailer Buy ex | AU4: Supplier Support | AV4: MG Support | AW4: Total Support | AX4: End to End Standard Margin | AY4: End to End Promo Margin | AZ4: Customer SOH | BA4: Customer 6wk Avg | BB4: Expected Sales / Actual Sales | BC4: Supplier Claim Amount | BD4: MacGear Claim Amount | BF4: Customer Code | BG4: Retailer Buy ex | BH4: Supplier Support | BI4: MG Support | BJ4: Total Support | BK4: End to End Standard Margin | BL4: End to End Promo Margin | BM4: Customer SOH | BN4: Customer 6wk Avg | BO4: Expected Sales / Actual Sales | BP4: Supplier Claim Amount | BQ4: MacGear Claim Amount | BS4: Customer Code | BT4: Retailer Buy ex | BU4: Supplier Support | BV4: MG Support | BW4: Total Support | BX4: End to End Standard Margin | BY4: End to End Promo Margin | BZ4: Customer SOH | CA4: Customer 6wk Avg | CB4: Expected Sales / Actual Sales | CC4: Supplier Claim Amount | CD4: MacGear Claim Amount | CF4: Customer Code | CG4: Retailer Buy ex | CH4: Supplier Support | CI4: MG Support | CJ4: Total Support | CK4: End to End Standard Margin | CL4: End to End Promo Margin | CM4: Customer SOH | CN4: Customer 6wk Avg | CO4: Expected Sales / Actual Sales | CP4: Supplier Claim Amount | CQ4: MacGear Claim Amount | CS4: RRP Inc | CT4: Recommended Sale Inc | CU4: Recommended % Off | CV4: Recommended $ Off | CW4: Comments
A5: 45809 | B5: 45822 | C5: A1902T11 | D5: =IF(C5="", "",_xlfn.XLOOKUP(C5,'Master Price Level'!C:C,'Master Price Level'!D:D)) -> ANKER 100W Charging Base for ANKER Prime Power Bank | F5: {=IFERROR(_xlfn._xlws.FILTER(ST[Customer Code],(ST[Code]=$C5) * (ST[Customer Name]=F$3),"" ),"")} | G5: {=IFERROR(_xlfn.XLOOKUP($C5,Query[Code], _xlfn.XLOOKUP('Promo Form'!F$3,Query[[#Headers],[Code]:[Bing Lee]],Query[[Code]:[Bing Lee]])),"")} -> 84.98 | H5: =IFERROR(((G5*(1-F$2))*$CU5)*F$61,"") -> 4.8956128 | I5: =IFERROR(((G5*(1-F$2))*$CU5)*F$60,"") -> 4.8956128 | J5: =IFERROR(IF(H5+I5=0,"",H5+I5),"") -> 9.7912256 | K5: =IFERROR((($CS5/1.1)-(G5-(G5*F$2)))/($CS5/1.1),"") -> 0.52422201 | L5: =IFERROR((($CT5/1.1)+(H5+I5)-(G5-(G5*F$2)))/($CT5/1.1),"") -> 0.48449454 | M5: {=IFERROR(_xlfn._xlws.FILTER(ST[SOH],(ST[Code]=$C5) * (ST[Customer Name]=F$3),"" ),"")} | N5: {=IFERROR( _xlfn.LET( _xlpm.result, INDEX(_xlfn._xlws.FILTER(ST[6wk avg], (ST[Code]=$C5)*(ST[Customer Name]=F$3), ""), 1), IF(_xlpm.result=0, "", _xlpm.result) ), "")} | O5: =IFERROR(IF(CEILING(N5 + (N5 * $O$2), 1) = 0, "", CEILING(N5 + (N5 * $O$2), 1))*$B$3, "") | P5: =IFERROR((O5*H5),"") | Q5: =IFERROR((O5*I5),"") | S5: {=IFERROR(_xlfn._xlws.FILTER(ST[Customer Code],(ST[Code]=$C5) * (ST[Customer Name]=S$3),"" ),"")} | T5: {=IFERROR(_xlfn.XLOOKUP($C5,Query[Code], _xlfn.XLOOKUP('Promo Form'!S$3,Query[[#Headers],[Code]:[Bing Lee]],Query[[Code]:[Bing Lee]])),"")} -> 0 | U5: =IFERROR(((T5*(1-S$2))*$CU5)*S$61,"") -> 0 | V5: =IFERROR(((T5*(1-S$2))*$CU5)*S$60,"") -> 0 | W5: =IFERROR(IF(U5+V5=0,"",U5+V5),"") | X5: =IFERROR((($CS5/1.1)-(T5-(T5*S$2)))/($CS5/1.1),"") -> 1 | Y5: =IFERROR((($CT5/1.1)+(U5+V5)-(T5-(T5*S$2)))/($CT5/1.1),"") -> 1 | Z5: {=IFERROR(_xlfn._xlws.FILTER(ST[SOH],(ST[Code]=$C5) * (ST[Customer Name]=S$3),"" ),"")} | AA5: {=IFERROR( _xlfn.LET( _xlpm.result, INDEX(_xlfn._xlws.FILTER(ST[6wk avg], (ST[Code]=$C5)*(ST[Customer Name]=S$3), ""), 1), IF(_xlpm.result=0, "", _xlpm.result) ), "")} | AB5: =IFERROR(IF(CEILING(AA5 + (AA5 * $AB$2), 1) = 0, "", CEILING(AA5 + (AA5 * $AB$2), 1))*$B$3, "") | AC5: =IFERROR((AB5*U5),"") | AD5: =IFERROR((AB5*V5),"") | AF5: {=IFERROR(_xlfn._xlws.FILTER(ST[Customer Code],(ST[Code]=$C5) * (ST[Customer Name]=AF$3),"" ),"")} | AG5: {=IFERROR(_xlfn.XLOOKUP($C5,Query[Code], _xlfn.XLOOKUP('Promo Form'!AF$3,Query[[#Headers],[Code]:[Bing Lee]],Query[[Code]:[Bing Lee]])),"")} -> 0 | AH5: =IFERROR(((AG5*(1-AF$2))*$CU5)*AF$61,"") -> 0 | AI5: =IFERROR(((AG5*(1-AF$2))*$CU5)*AF$60,"") -> 0 | AJ5: =IFERROR(IF(AH5+AI5=0,"",AH5+AI5),"") | AK5: =IFERROR((($CS5/1.1)-(AG5-(AG5*AF$2)))/($CS5/1.1),"") -> 1 | AL5: =IFERROR((($CT5/1.1)+(AH5+AI5)-(AG5-(AG5*AF$2)))/($CT5/1.1),"") -> 1 | AM5: {=IFERROR(_xlfn._xlws.FILTER(ST[SOH],(ST[Code]=$C5) * (ST[Customer Name]=AF$3),"" ),"")} | AN5: {=IFERROR( _xlfn.LET( _xlpm.result, INDEX(_xlfn._xlws.FILTER(ST[6wk avg], (ST[Code]=$C5)*(ST[Customer Name]=AF$3), ""), 1), IF(_xlpm.result=0, "", _xlpm.result) ), "")} | AO5: =IFERROR(IF(CEILING(AN5 + (AN5 * $AO$2), 1) = 0, "", CEILING(AN5 + (AN5 * $AO$2), 1))*$B$3, "") | AP5: =IFERROR((AO5*AH5),"") | AQ5: =IFERROR((AO5*AI5),"") | AS5: {=IFERROR(_xlfn._xlws.FILTER(ST[Customer Code],(ST[Code]=$C5) * (ST[Customer Name]=AS$3),"" ),"")} | AT5: {=IFERROR(_xlfn.XLOOKUP($C5,Query[Code], _xlfn.XLOOKUP('Promo Form'!AS$3,Query[[#Headers],[Code]:[Bing Lee]],Query[[Code]:[Bing Lee]])),"")} -> 0 | AU5: =IFERROR(((AT5*(1-AS$2))*$CU5)*AS$61,"") -> 0 | AV5: =IFERROR(((AT5*(1-AS$2))*$CU5)*AS$60,"") -> 0 | AW5: =IFERROR(IF(AU5+AV5=0,"",AU5+AV5),"") | AX5: =IFERROR((($CS5/1.1)-(AT5-(AT5*AS$2)))/($CS5/1.1),"") -> 1 | AY5: =IFERROR((($CT5/1.1)+(AU5+AV5)-(AT5-(AT5*AS$2)))/($CT5/1.1),"") -> 1 | AZ5: {=IFERROR(_xlfn._xlws.FILTER(ST[SOH],(ST[Code]=$C5) * (ST[Customer Name]=AS$3),"" ),"")} | BA5: {=IFERROR( _xlfn.LET( _xlpm.result, INDEX(_xlfn._xlws.FILTER(ST[6wk avg], (ST[Code]=$C5)*(ST[Customer Name]=AS$3), ""), 1), IF(_xlpm.result=0, "", _xlpm.result) ), "")} | BB5: =IFERROR(IF(CEILING(BA5 + (BA5 * $BB$2), 1) = 0, "", CEILING(BA5 + (BA5 * $BB$2), 1))*$B$3, "") | BC5: =IFERROR((BB5*AU5),"") | BD5: =IFERROR((BB5*AV5),"") | BF5: {=IFERROR(_xlfn._xlws.FILTER(ST[Customer Code],(ST[Code]=$C5) * (ST[Customer Name]=BF$3),"" ),"")} | BG5: {=IFERROR(_xlfn.XLOOKUP($C5,Query[Code], _xlfn.XLOOKUP('Promo Form'!BF$3,Query[[#Headers],[Code]:[Bing Lee]],Query[[Code]:[Bing Lee]])),"")} -> 0 | BH5: =IFERROR(((BG5*(1-BF$2))*$CU5)*BF$61,"") -> 0 | BI5: =IFERROR(((BG5*(1-BF$2))*$CU5)*BF$60,"") -> 0 | BJ5: =IFERROR(IF(BH5+BI5=0,"",BH5+BI5),"") | BK5: =IFERROR((($CS5/1.1)-(BG5-(BG5*BF$2)))/($CS5/1.1),"") -> 1 | BL5: =IFERROR((($CT5/1.1)+(BH5+BI5)-(BG5-(BG5*BF$2)))/($CT5/1.1),"") -> 1 | BM5: {=IFERROR(_xlfn._xlws.FILTER(ST[SOH],(ST[Code]=$C5) * (ST[Customer Name]=BF$3),"" ),"")} | BN5: {=IFERROR( _xlfn.LET( _xlpm.result, INDEX(_xlfn._xlws.FILTER(ST[6wk avg], (ST[Code]=$C5)*(ST[Customer Name]=BF$3), ""), 1), IF(_xlpm.result=0, "", _xlpm.result) ), "")} | BO5: =IFERROR(IF(CEILING(BN5 + (BN5 * $BO$2), 1) = 0, "", CEILING(BN5 + (BN5 * $BO$2), 1))*$B$3, "") | BP5: =IFERROR((BO5*BH5),"") | BQ5: =IFERROR((BO5*BI5),"") | BS5: {=IFERROR(_xlfn._xlws.FILTER(ST[Customer Code],(ST[Code]=$C5) * (ST[Customer Name]=BS$3),"" ),"")} | BT5: {=IFERROR(_xlfn.XLOOKUP($C5,Query[Code], _xlfn.XLOOKUP('Promo Form'!BS$3,Query[[#Headers],[Code]:[Bing Lee]],Query[[Code]:[Bing Lee]])),"")} -> 92.7 | BU5: =IFERROR(((BT5*(1-BS$2))*$CU5)*BS$61,"") -> 5.1242706 | BV5: =IFERROR(((BT5*(1-BS$2))*$CU5)*BS$60,"") -> 5.1242706 | BW5: =IFERROR(IF(BU5+BV5=0,"",BU5+BV5),"") -> 10.248541 | BX5: =IFERROR((($CS5/1.1)-(BT5-(BT5*BS$2)))/($CS5/1.1),"") -> 0.502 | BY5: =IFERROR((($CT5/1.1)+(BU5+BV5)-(BT5-(BT5*BS$2)))/($CT5/1.1),"") -> 0.460417 | BZ5: {=IFERROR(_xlfn._xlws.FILTER(ST[SOH],(ST[Code]=$C5) * (ST[Customer Name]=BS$3),"" ),"")} | CA5: {=IFERROR( _xlfn.LET( _xlpm.result, INDEX(_xlfn._xlws.FILTER(ST[6wk avg], (ST[Code]=$C5)*(ST[Customer Name]=BS$3), ""), 1), IF(_xlpm.result=0, "", _xlpm.result) ), "")} | CB5: =IFERROR(IF(CEILING(CA5 + (CA5 * $CB$2), 1) = 0, "", CEILING(CA5 + (CA5 * $CB$2), 1))*$B$3, "") | CC5: =IFERROR((CB5*BU5),"") | CD5: =IFERROR((CB5*BV5),"") | CF5: {=IFERROR(_xlfn._xlws.FILTER(ST[Customer Code],(ST[Code]=$C5) * (ST[Customer Name]=CF$3),"" ),"")} | CG5: {=IFERROR(_xlfn.XLOOKUP($C5,Query[Code], _xlfn.XLOOKUP('Promo Form'!CF$3,Query[[#Headers],[Code]:[Bing Lee]],Query[[Code]:[Bing Lee]])),"")} -> 92.7 | CH5: =IFERROR(((CG5*(1-CF$2))*$CU5)*CF$61,"") -> 5.1242706 | CI5: =IFERROR(((CG5*(1-CF$2))*$CU5)*CF$60,"") -> 5.1242706 | CJ5: =IFERROR(IF(CH5+CI5=0,"",CH5+CI5),"") -> 10.248541 | CK5: =IFERROR((($CS5/1.1)-(CG5-(CG5*CF$2)))/($CS5/1.1),"") -> 0.502 | CL5: =IFERROR((($CT5/1.1)+(CH5+CI5)-(CG5-(CG5*CF$2)))/($CT5/1.1),"") -> 0.460417 | CM5: {=IFERROR(_xlfn._xlws.FILTER(ST[SOH],(ST[Code]=$C5) * (ST[Customer Name]=CF$3),"" ),"")} | CN5: {=IFERROR( _xlfn.LET( _xlpm.result, INDEX(_xlfn._xlws.FILTER(ST[6wk avg], (ST[Code]=$C5)*(ST[Customer Name]=CF$3), ""), 1), IF(_xlpm.result=0, "", _xlpm.result) ), "")} | CO5: =IFERROR(IF(CEILING(CN5 + (CN5 * $CO$2), 1) = 0, "", CEILING(CN5 + (CN5 * $CO$2), 1))*$B$3, "") | CP5: =IFERROR((CO5*CH5),"") | CQ5: =IFERROR((CO5*CI5),"") | CS5: =IFERROR(_xlfn.XLOOKUP(C5,Query[Code],Query[Base (RRP Inc)]),"") -> 169.95 | CT5: =IFERROR(CS5-(CS5*CU5),"") -> 135.96 | CU5: 0.2 | CV5: =IFERROR((CS5-CT5),"") -> 33.99
A6: =IF(C6="","",$A$5) | B6: =IF(C6="","",$B$5) | D6: =IF(C6="", "",_xlfn.XLOOKUP(C6,'Master Price Level'!C:C,'Master Price Level'!D:D)) | F6: {=IFERROR(_xlfn._xlws.FILTER(ST[Customer Code],(ST[Code]=$C6) * (ST[Customer Name]=F$3),"" ),"")} | G6: {=IFERROR(_xlfn.XLOOKUP($C6,Query[Code], _xlfn.XLOOKUP('Promo Form'!F$3,Query[[#Headers],[Code]:[Bing Lee]],Query[[Code]:[Bing Lee]])),"")} | H6: =IFERROR(((G6*(1-F$2))*$CU6)*F$61,"") | I6: =IFERROR(((G6*(1-F$2))*$CU6)*F$60,"") | J6: =IFERROR(IF(H6+I6=0,"",H6+I6),"") | K6: =IFERROR((($CS6/1.1)-(G6-(G6*F$2)))/($CS6/1.1),"") | L6: =IFERROR((($CT6/1.1)+(H6+I6)-(G6-(G6*F$2)))/($CT6/1.1),"") | M6: {=IFERROR(_xlfn._xlws.FILTER(ST[SOH],(ST[Code]=$C6) * (ST[Customer Name]=F$3),"" ),"")} | N6: {=IFERROR( _xlfn.LET( _xlpm.result, INDEX(_xlfn._xlws.FILTER(ST[6wk avg], (ST[Code]=$C6)*(ST[Customer Name]=F$3), ""), 1), IF(_xlpm.result=0, "", _xlpm.result) ), "")} | O6: =IFERROR(IF(CEILING(N6 + (N6 * $O$2), 1) = 0, "", CEILING(N6 + (N6 * $O$2), 1))*$B$3, "") | P6: =IFERROR((O6*H6),"") | Q6: =IFERROR((O6*I6),"") | S6: {=IFERROR(_xlfn._xlws.FILTER(ST[Customer Code],(ST[Code]=$C6) * (ST[Customer Name]=S$3),"" ),"")} | T6: {=IFERROR(_xlfn.XLOOKUP($C6,Query[Code], _xlfn.XLOOKUP('Promo Form'!S$3,Query[[#Headers],[Code]:[Bing Lee]],Query[[Code]:[Bing Lee]])),"")} | U6: =IFERROR(((T6*(1-S$2))*$CU6)*S$61,"") | V6: =IFERROR(((T6*(1-S$2))*$CU6)*S$60,"") | W6: =IFERROR(IF(U6+V6=0,"",U6+V6),"") | X6: =IFERROR((($CS6/1.1)-(T6-(T6*S$2)))/($CS6/1.1),"") | Y6: =IFERROR((($CT6/1.1)+(U6+V6)-(T6-(T6*S$2)))/($CT6/1.1),"") | Z6: {=IFERROR(_xlfn._xlws.FILTER(ST[SOH],(ST[Code]=$C6) * (ST[Customer Name]=S$3),"" ),"")} | AA6: {=IFERROR( _xlfn.LET( _xlpm.result, INDEX(_xlfn._xlws.FILTER(ST[6wk avg], (ST[Code]=$C6)*(ST[Customer Name]=S$3), ""), 1), IF(_xlpm.result=0, "", _xlpm.result) ), "")} | AB6: =IFERROR(IF(CEILING(AA6 + (AA6 * $AB$2), 1) = 0, "", CEILING(AA6 + (AA6 * $AB$2), 1))*$B$3, "") | AC6: =IFERROR((AB6*U6),"") | AD6: =IFERROR((AB6*V6),"") | AF6: {=IFERROR(_xlfn._xlws.FILTER(ST[Customer Code],(ST[Code]=$C6) * (ST[Customer Name]=AF$3),"" ),"")} | AG6: {=IFERROR(_xlfn.XLOOKUP($C6,Query[Code], _xlfn.XLOOKUP('Promo Form'!AF$3,Query[[#Headers],[Code]:[Bing Lee]],Query[[Code]:[Bing Lee]])),"")} | AH6: =IFERROR(((AG6*(1-AF$2))*$CU6)*AF$61,"") | AI6: =IFERROR(((AG6*(1-AF$2))*$CU6)*AF$60,"") | AJ6: =IFERROR(IF(AH6+AI6=0,"",AH6+AI6),"") | AK6: =IFERROR((($CS6/1.1)-(AG6-(AG6*AF$2)))/($CS6/1.1),"") | AL6: =IFERROR((($CT6/1.1)+(AH6+AI6)-(AG6-(AG6*AF$2)))/($CT6/1.1),"") | AM6: {=IFERROR(_xlfn._xlws.FILTER(ST[SOH],(ST[Code]=$C6) * (ST[Customer Name]=AF$3),"" ),"")} | AN6: {=IFERROR( _xlfn.LET( _xlpm.result, INDEX(_xlfn._xlws.FILTER(ST[6wk avg], (ST[Code]=$C6)*(ST[Customer Name]=AF$3), ""), 1), IF(_xlpm.result=0, "", _xlpm.result) ), "")} | AO6: =IFERROR(IF(CEILING(AN6 + (AN6 * $AO$2), 1) = 0, "", CEILING(AN6 + (AN6 * $AO$2), 1))*$B$3, "") | AP6: =IFERROR((AO6*AH6),"") | AQ6: =IFERROR((AO6*AI6),"") | AS6: {=IFERROR(_xlfn._xlws.FILTER(ST[Customer Code],(ST[Code]=$C6) * (ST[Customer Name]=AS$3),"" ),"")} | AT6: {=IFERROR(_xlfn.XLOOKUP($C6,Query[Code], _xlfn.XLOOKUP('Promo Form'!AS$3,Query[[#Headers],[Code]:[Bing Lee]],Query[[Code]:[Bing Lee]])),"")} | AU6: =IFERROR(((AT6*(1-AS$2))*$CU6)*AS$61,"") | AV6: =IFERROR(((AT6*(1-AS$2))*$CU6)*AS$60,"") | AW6: =IFERROR(IF(AU6+AV6=0,"",AU6+AV6),"") | AX6: =IFERROR((($CS6/1.1)-(AT6-(AT6*AS$2)))/($CS6/1.1),"") | AY6: =IFERROR((($CT6/1.1)+(AU6+AV6)-(AT6-(AT6*AS$2)))/($CT6/1.1),"") | AZ6: {=IFERROR(_xlfn._xlws.FILTER(ST[SOH],(ST[Code]=$C6) * (ST[Customer Name]=AS$3),"" ),"")} | BA6: {=IFERROR( _xlfn.LET( _xlpm.result, INDEX(_xlfn._xlws.FILTER(ST[6wk avg], (ST[Code]=$C6)*(ST[Customer Name]=AS$3), ""), 1), IF(_xlpm.result=0, "", _xlpm.result) ), "")} | BB6: =IFERROR(IF(CEILING(BA6 + (BA6 * $BB$2), 1) = 0, "", CEILING(BA6 + (BA6 * $BB$2), 1))*$B$3, "") | BC6: =IFERROR((BB6*AU6),"") | BD6: =IFERROR((BB6*AV6),"") | BF6: {=IFERROR(_xlfn._xlws.FILTER(ST[Customer Code],(ST[Code]=$C6) * (ST[Customer Name]=BF$3),"" ),"")} | BG6: {=IFERROR(_xlfn.XLOOKUP($C6,Query[Code], _xlfn.XLOOKUP('Promo Form'!BF$3,Query[[#Headers],[Code]:[Bing Lee]],Query[[Code]:[Bing Lee]])),"")} | BH6: =IFERROR(((BG6*(1-BF$2))*$CU6)*BF$61,"") | BI6: =IFERROR(((BG6*(1-BF$2))*$CU6)*BF$60,"") | BJ6: =IFERROR(IF(BH6+BI6=0,"",BH6+BI6),"") | BK6: =IFERROR((($CS6/1.1)-(BG6-(BG6*BF$2)))/($CS6/1.1),"") | BL6: =IFERROR((($CT6/1.1)+(BH6+BI6)-(BG6-(BG6*BF$2)))/($CT6/1.1),"") | BM6: {=IFERROR(_xlfn._xlws.FILTER(ST[SOH],(ST[Code]=$C6) * (ST[Customer Name]=BF$3),"" ),"")} | BN6: {=IFERROR( _xlfn.LET( _xlpm.result, INDEX(_xlfn._xlws.FILTER(ST[6wk avg], (ST[Code]=$C6)*(ST[Customer Name]=BF$3), ""), 1), IF(_xlpm.result=0, "", _xlpm.result) ), "")} | BO6: =IFERROR(IF(CEILING(BN6 + (BN6 * $BO$2), 1) = 0, "", CEILING(BN6 + (BN6 * $BO$2), 1))*$B$3, "") | BP6: =IFERROR((BO6*BH6),"") | BQ6: =IFERROR((BO6*BI6),"") | BS6: {=IFERROR(_xlfn._xlws.FILTER(ST[Customer Code],(ST[Code]=$C6) * (ST[Customer Name]=BS$3),"" ),"")} | BT6: {=IFERROR(_xlfn.XLOOKUP($C6,Query[Code], _xlfn.XLOOKUP('Promo Form'!BS$3,Query[[#Headers],[Code]:[Bing Lee]],Query[[Code]:[Bing Lee]])),"")} | BU6: =IFERROR(((BT6*(1-BS$2))*$CU6)*BS$61,"") | BV6: =IFERROR(((BT6*(1-BS$2))*$CU6)*BS$60,"") | BW6: =IFERROR(IF(BU6+BV6=0,"",BU6+BV6),"") | BX6: =IFERROR((($CS6/1.1)-(BT6-(BT6*BS$2)))/($CS6/1.1),"") | BY6: =IFERROR((($CT6/1.1)+(BU6+BV6)-(BT6-(BT6*BS$2)))/($CT6/1.1),"") | BZ6: {=IFERROR(_xlfn._xlws.FILTER(ST[SOH],(ST[Code]=$C6) * (ST[Customer Name]=BS$3),"" ),"")} | CA6: {=IFERROR( _xlfn.LET( _xlpm.result, INDEX(_xlfn._xlws.FILTER(ST[6wk avg], (ST[Code]=$C6)*(ST[Customer Name]=BS$3), ""), 1), IF(_xlpm.result=0, "", _xlpm.result) ), "")} | CB6: =IFERROR(IF(CEILING(CA6 + (CA6 * $CB$2), 1) = 0, "", CEILING(CA6 + (CA6 * $CB$2), 1))*$B$3, "") | CC6: =IFERROR((CB6*BU6),"") | CD6: =IFERROR((CB6*BV6),"") | CF6: {=IFERROR(_xlfn._xlws.FILTER(ST[Customer Code],(ST[Code]=$C6) * (ST[Customer Name]=CF$3),"" ),"")} | CG6: {=IFERROR(_xlfn.XLOOKUP($C6,Query[Code], _xlfn.XLOOKUP('Promo Form'!CF$3,Query[[#Headers],[Code]:[Bing Lee]],Query[[Code]:[Bing Lee]])),"")} | CH6: =IFERROR(((CG6*(1-CF$2))*$CU6)*CF$61,"") | CI6: =IFERROR(((CG6*(1-CF$2))*$CU6)*CF$60,"") | CJ6: =IFERROR(IF(CH6+CI6=0,"",CH6+CI6),"") | CK6: =IFERROR((($CS6/1.1)-(CG6-(CG6*CF$2)))/($CS6/1.1),"") | CL6: =IFERROR((($CT6/1.1)+(CH6+CI6)-(CG6-(CG6*CF$2)))/($CT6/1.1),"") | CM6: {=IFERROR(_xlfn._xlws.FILTER(ST[SOH],(ST[Code]=$C6) * (ST[Customer Name]=CF$3),"" ),"")} | CN6: {=IFERROR( _xlfn.LET( _xlpm.result, INDEX(_xlfn._xlws.FILTER(ST[6wk avg], (ST[Code]=$C6)*(ST[Customer Name]=CF$3), ""), 1), IF(_xlpm.result=0, "", _xlpm.result) ), "")} | CO6: =IFERROR(IF(CEILING(CN6 + (CN6 * $CO$2), 1) = 0, "", CEILING(CN6 + (CN6 * $CO$2), 1))*$B$3, "") | CP6: =IFERROR((CO6*CH6),"") | CQ6: =IFERROR((CO6*CI6),"") | CS6: =IFERROR(_xlfn.XLOOKUP(C6,Query[Code],Query[Base (RRP Inc)]),"") | CT6: =IFERROR(CS6-(CS6*CU6),"") | CU6: =IF(C6="", "",CU5) | CV6: =IFERROR((CS6-CT6),"")
A7: =IF(C7="","",A6) | B7: =IF(C7="","",B6) | D7: =IF(C7="", "",_xlfn.XLOOKUP(C7,'Master Price Level'!C:C,'Master Price Level'!D:D)) | F7: {=IFERROR(_xlfn._xlws.FILTER(ST[Customer Code],(ST[Code]=$C7) * (ST[Customer Name]=F$3),"" ),"")} | G7: {=IFERROR(_xlfn.XLOOKUP($C7,Query[Code], _xlfn.XLOOKUP('Promo Form'!F$3,Query[[#Headers],[Code]:[Bing Lee]],Query[[Code]:[Bing Lee]])),"")} | H7: =IFERROR(((G7*(1-F$2))*$CU7)*F$61,"") | I7: =IFERROR(((G7*(1-F$2))*$CU7)*F$60,"") | J7: =IFERROR(IF(H7+I7=0,"",H7+I7),"") | K7: =IFERROR((($CS7/1.1)-(G7-(G7*F$2)))/($CS7/1.1),"") | L7: =IFERROR((($CT7/1.1)+(H7+I7)-(G7-(G7*F$2)))/($CT7/1.1),"") | M7: {=IFERROR(_xlfn._xlws.FILTER(ST[SOH],(ST[Code]=$C7) * (ST[Customer Name]=F$3),"" ),"")} | N7: {=IFERROR( _xlfn.LET( _xlpm.result, INDEX(_xlfn._xlws.FILTER(ST[6wk avg], (ST[Code]=$C7)*(ST[Customer Name]=F$3), ""), 1), IF(_xlpm.result=0, "", _xlpm.result) ), "")} | O7: =IFERROR(IF(CEILING(N7 + (N7 * $O$2), 1) = 0, "", CEILING(N7 + (N7 * $O$2), 1))*$B$3, "") | P7: =IFERROR((O7*H7),"") | Q7: =IFERROR((O7*I7),"") | S7: {=IFERROR(_xlfn._xlws.FILTER(ST[Customer Code],(ST[Code]=$C7) * (ST[Customer Name]=S$3),"" ),"")} | T7: {=IFERROR(_xlfn.XLOOKUP($C7,Query[Code], _xlfn.XLOOKUP('Promo Form'!S$3,Query[[#Headers],[Code]:[Bing Lee]],Query[[Code]:[Bing Lee]])),"")} | U7: =IFERROR(((T7*(1-S$2))*$CU7)*S$61,"") | V7: =IFERROR(((T7*(1-S$2))*$CU7)*S$60,"") | W7: =IFERROR(IF(U7+V7=0,"",U7+V7),"") | X7: =IFERROR((($CS7/1.1)-(T7-(T7*S$2)))/($CS7/1.1),"") | Y7: =IFERROR((($CT7/1.1)+(U7+V7)-(T7-(T7*S$2)))/($CT7/1.1),"") | Z7: {=IFERROR(_xlfn._xlws.FILTER(ST[SOH],(ST[Code]=$C7) * (ST[Customer Name]=S$3),"" ),"")} | AA7: {=IFERROR( _xlfn.LET( _xlpm.result, INDEX(_xlfn._xlws.FILTER(ST[6wk avg], (ST[Code]=$C7)*(ST[Customer Name]=S$3), ""), 1), IF(_xlpm.result=0, "", _xlpm.result) ), "")} | AB7: =IFERROR(IF(CEILING(AA7 + (AA7 * $AB$2), 1) = 0, "", CEILING(AA7 + (AA7 * $AB$2), 1))*$B$3, "") | AC7: =IFERROR((AB7*U7),"") | AD7: =IFERROR((AB7*V7),"") | AF7: {=IFERROR(_xlfn._xlws.FILTER(ST[Customer Code],(ST[Code]=$C7) * (ST[Customer Name]=AF$3),"" ),"")} | AG7: {=IFERROR(_xlfn.XLOOKUP($C7,Query[Code], _xlfn.XLOOKUP('Promo Form'!AF$3,Query[[#Headers],[Code]:[Bing Lee]],Query[[Code]:[Bing Lee]])),"")} | AH7: =IFERROR(((AG7*(1-AF$2))*$CU7)*AF$61,"") | AI7: =IFERROR(((AG7*(1-AF$2))*$CU7)*AF$60,"") | AJ7: =IFERROR(IF(AH7+AI7=0,"",AH7+AI7),"") | AK7: =IFERROR((($CS7/1.1)-(AG7-(AG7*AF$2)))/($CS7/1.1),"") | AL7: =IFERROR((($CT7/1.1)+(AH7+AI7)-(AG7-(AG7*AF$2)))/($CT7/1.1),"") | AM7: {=IFERROR(_xlfn._xlws.FILTER(ST[SOH],(ST[Code]=$C7) * (ST[Customer Name]=AF$3),"" ),"")} | AN7: {=IFERROR( _xlfn.LET( _xlpm.result, INDEX(_xlfn._xlws.FILTER(ST[6wk avg], (ST[Code]=$C7)*(ST[Customer Name]=AF$3), ""), 1), IF(_xlpm.result=0, "", _xlpm.result) ), "")} | AO7: =IFERROR(IF(CEILING(AN7 + (AN7 * $AO$2), 1) = 0, "", CEILING(AN7 + (AN7 * $AO$2), 1))*$B$3, "") | AP7: =IFERROR((AO7*AH7),"") | AQ7: =IFERROR((AO7*AI7),"") | AS7: {=IFERROR(_xlfn._xlws.FILTER(ST[Customer Code],(ST[Code]=$C7) * (ST[Customer Name]=AS$3),"" ),"")} | AT7: {=IFERROR(_xlfn.XLOOKUP($C7,Query[Code], _xlfn.XLOOKUP('Promo Form'!AS$3,Query[[#Headers],[Code]:[Bing Lee]],Query[[Code]:[Bing Lee]])),"")} | AU7: =IFERROR(((AT7*(1-AS$2))*$CU7)*AS$61,"") | AV7: =IFERROR(((AT7*(1-AS$2))*$CU7)*AS$60,"") | AW7: =IFERROR(IF(AU7+AV7=0,"",AU7+AV7),"") | AX7: =IFERROR((($CS7/1.1)-(AT7-(AT7*AS$2)))/($CS7/1.1),"") | AY7: =IFERROR((($CT7/1.1)+(AU7+AV7)-(AT7-(AT7*AS$2)))/($CT7/1.1),"") | AZ7: {=IFERROR(_xlfn._xlws.FILTER(ST[SOH],(ST[Code]=$C7) * (ST[Customer Name]=AS$3),"" ),"")} | BA7: {=IFERROR( _xlfn.LET( _xlpm.result, INDEX(_xlfn._xlws.FILTER(ST[6wk avg], (ST[Code]=$C7)*(ST[Customer Name]=AS$3), ""), 1), IF(_xlpm.result=0, "", _xlpm.result) ), "")} | BB7: =IFERROR(IF(CEILING(BA7 + (BA7 * $BB$2), 1) = 0, "", CEILING(BA7 + (BA7 * $BB$2), 1))*$B$3, "") | BC7: =IFERROR((BB7*AU7),"") | BD7: =IFERROR((BB7*AV7),"") | BF7: {=IFERROR(_xlfn._xlws.FILTER(ST[Customer Code],(ST[Code]=$C7) * (ST[Customer Name]=BF$3),"" ),"")} | BG7: {=IFERROR(_xlfn.XLOOKUP($C7,Query[Code], _xlfn.XLOOKUP('Promo Form'!BF$3,Query[[#Headers],[Code]:[Bing Lee]],Query[[Code]:[Bing Lee]])),"")} | BH7: =IFERROR(((BG7*(1-BF$2))*$CU7)*BF$61,"") | BI7: =IFERROR(((BG7*(1-BF$2))*$CU7)*BF$60,"") | BJ7: =IFERROR(IF(BH7+BI7=0,"",BH7+BI7),"") | BK7: =IFERROR((($CS7/1.1)-(BG7-(BG7*BF$2)))/($CS7/1.1),"") | BL7: =IFERROR((($CT7/1.1)+(BH7+BI7)-(BG7-(BG7*BF$2)))/($CT7/1.1),"") | BM7: {=IFERROR(_xlfn._xlws.FILTER(ST[SOH],(ST[Code]=$C7) * (ST[Customer Name]=BF$3),"" ),"")} | BN7: {=IFERROR( _xlfn.LET( _xlpm.result, INDEX(_xlfn._xlws.FILTER(ST[6wk avg], (ST[Code]=$C7)*(ST[Customer Name]=BF$3), ""), 1), IF(_xlpm.result=0, "", _xlpm.result) ), "")} | BO7: =IFERROR(IF(CEILING(BN7 + (BN7 * $BO$2), 1) = 0, "", CEILING(BN7 + (BN7 * $BO$2), 1))*$B$3, "") | BP7: =IFERROR((BO7*BH7),"") | BQ7: =IFERROR((BO7*BI7),"") | BS7: {=IFERROR(_xlfn._xlws.FILTER(ST[Customer Code],(ST[Code]=$C7) * (ST[Customer Name]=BS$3),"" ),"")} | BT7: {=IFERROR(_xlfn.XLOOKUP($C7,Query[Code], _xlfn.XLOOKUP('Promo Form'!BS$3,Query[[#Headers],[Code]:[Bing Lee]],Query[[Code]:[Bing Lee]])),"")} | BU7: =IFERROR(((BT7*(1-BS$2))*$CU7)*BS$61,"") | BV7: =IFERROR(((BT7*(1-BS$2))*$CU7)*BS$60,"") | BW7: =IFERROR(IF(BU7+BV7=0,"",BU7+BV7),"") | BX7: =IFERROR((($CS7/1.1)-(BT7-(BT7*BS$2)))/($CS7/1.1),"") | BY7: =IFERROR((($CT7/1.1)+(BU7+BV7)-(BT7-(BT7*BS$2)))/($CT7/1.1),"") | BZ7: {=IFERROR(_xlfn._xlws.FILTER(ST[SOH],(ST[Code]=$C7) * (ST[Customer Name]=BS$3),"" ),"")} | CA7: {=IFERROR( _xlfn.LET( _xlpm.result, INDEX(_xlfn._xlws.FILTER(ST[6wk avg], (ST[Code]=$C7)*(ST[Customer Name]=BS$3), ""), 1), IF(_xlpm.result=0, "", _xlpm.result) ), "")} | CB7: =IFERROR(IF(CEILING(CA7 + (CA7 * $CB$2), 1) = 0, "", CEILING(CA7 + (CA7 * $CB$2), 1))*$B$3, "") | CC7: =IFERROR((CB7*BU7),"") | CD7: =IFERROR((CB7*BV7),"") | CF7: {=IFERROR(_xlfn._xlws.FILTER(ST[Customer Code],(ST[Code]=$C7) * (ST[Customer Name]=CF$3),"" ),"")} | CG7: {=IFERROR(_xlfn.XLOOKUP($C7,Query[Code], _xlfn.XLOOKUP('Promo Form'!CF$3,Query[[#Headers],[Code]:[Bing Lee]],Query[[Code]:[Bing Lee]])),"")} | CH7: =IFERROR(((CG7*(1-CF$2))*$CU7)*CF$61,"") | CI7: =IFERROR(((CG7*(1-CF$2))*$CU7)*CF$60,"") | CJ7: =IFERROR(IF(CH7+CI7=0,"",CH7+CI7),"") | CK7: =IFERROR((($CS7/1.1)-(CG7-(CG7*CF$2)))/($CS7/1.1),"") | CL7: =IFERROR((($CT7/1.1)+(CH7+CI7)-(CG7-(CG7*CF$2)))/($CT7/1.1),"") | CM7: {=IFERROR(_xlfn._xlws.FILTER(ST[SOH],(ST[Code]=$C7) * (ST[Customer Name]=CF$3),"" ),"")} | CN7: {=IFERROR( _xlfn.LET( _xlpm.result, INDEX(_xlfn._xlws.FILTER(ST[6wk avg], (ST[Code]=$C7)*(ST[Customer Name]=CF$3), ""), 1), IF(_xlpm.result=0, "", _xlpm.result) ), "")} | CO7: =IFERROR(IF(CEILING(CN7 + (CN7 * $CO$2), 1) = 0, "", CEILING(CN7 + (CN7 * $CO$2), 1))*$B$3, "") | CP7: =IFERROR((CO7*CH7),"") | CQ7: =IFERROR((CO7*CI7),"") | CS7: =IFERROR(_xlfn.XLOOKUP(C7,Query[Code],Query[Base (RRP Inc)]),"") | CT7: =IFERROR(CS7-(CS7*CU7),"") | CU7: =IF(C7="", "",CU6) | CV7: =IFERROR((CS7-CT7),"")
A8: =IF(C8="","",A7) | B8: =IF(C8="","",B7) | D8: =IF(C8="", "",_xlfn.XLOOKUP(C8,'Master Price Level'!C:C,'Master Price Level'!D:D)) | F8: {=IFERROR(_xlfn._xlws.FILTER(ST[Customer Code],(ST[Code]=$C8) * (ST[Customer Name]=F$3),"" ),"")} | G8: {=IFERROR(_xlfn.XLOOKUP($C8,Query[Code], _xlfn.XLOOKUP('Promo Form'!F$3,Query[[#Headers],[Code]:[Bing Lee]],Query[[Code]:[Bing Lee]])),"")} | H8: =IFERROR(((G8*(1-F$2))*$CU8)*F$61,"") | I8: =IFERROR(((G8*(1-F$2))*$CU8)*F$60,"") | J8: =IFERROR(IF(H8+I8=0,"",H8+I8),"") | K8: =IFERROR((($CS8/1.1)-(G8-(G8*F$2)))/($CS8/1.1),"") | L8: =IFERROR((($CT8/1.1)+(H8+I8)-(G8-(G8*F$2)))/($CT8/1.1),"") | M8: {=IFERROR(_xlfn._xlws.FILTER(ST[SOH],(ST[Code]=$C8) * (ST[Customer Name]=F$3),"" ),"")} | N8: {=IFERROR( _xlfn.LET( _xlpm.result, INDEX(_xlfn._xlws.FILTER(ST[6wk avg], (ST[Code]=$C8)*(ST[Customer Name]=F$3), ""), 1), IF(_xlpm.result=0, "", _xlpm.result) ), "")} | O8: =IFERROR(IF(CEILING(N8 + (N8 * $O$2), 1) = 0, "", CEILING(N8 + (N8 * $O$2), 1))*$B$3, "") | P8: =IFERROR((O8*H8),"") | Q8: =IFERROR((O8*I8),"") | S8: {=IFERROR(_xlfn._xlws.FILTER(ST[Customer Code],(ST[Code]=$C8) * (ST[Customer Name]=S$3),"" ),"")} | T8: {=IFERROR(_xlfn.XLOOKUP($C8,Query[Code], _xlfn.XLOOKUP('Promo Form'!S$3,Query[[#Headers],[Code]:[Bing Lee]],Query[[Code]:[Bing Lee]])),"")} | U8: =IFERROR(((T8*(1-S$2))*$CU8)*S$61,"") | V8: =IFERROR(((T8*(1-S$2))*$CU8)*S$60,"") | W8: =IFERROR(IF(U8+V8=0,"",U8+V8),"") | X8: =IFERROR((($CS8/1.1)-(T8-(T8*S$2)))/($CS8/1.1),"") | Y8: =IFERROR((($CT8/1.1)+(U8+V8)-(T8-(T8*S$2)))/($CT8/1.1),"") | Z8: {=IFERROR(_xlfn._xlws.FILTER(ST[SOH],(ST[Code]=$C8) * (ST[Customer Name]=S$3),"" ),"")} | AA8: {=IFERROR( _xlfn.LET( _xlpm.result, INDEX(_xlfn._xlws.FILTER(ST[6wk avg], (ST[Code]=$C8)*(ST[Customer Name]=S$3), ""), 1), IF(_xlpm.result=0, "", _xlpm.result) ), "")} | AB8: =IFERROR(IF(CEILING(AA8 + (AA8 * $AB$2), 1) = 0, "", CEILING(AA8 + (AA8 * $AB$2), 1))*$B$3, "") | AC8: =IFERROR((AB8*U8),"") | AD8: =IFERROR((AB8*V8),"") | AF8: {=IFERROR(_xlfn._xlws.FILTER(ST[Customer Code],(ST[Code]=$C8) * (ST[Customer Name]=AF$3),"" ),"")} | AG8: {=IFERROR(_xlfn.XLOOKUP($C8,Query[Code], _xlfn.XLOOKUP('Promo Form'!AF$3,Query[[#Headers],[Code]:[Bing Lee]],Query[[Code]:[Bing Lee]])),"")} | AH8: =IFERROR(((AG8*(1-AF$2))*$CU8)*AF$61,"") | AI8: =IFERROR(((AG8*(1-AF$2))*$CU8)*AF$60,"") | AJ8: =IFERROR(IF(AH8+AI8=0,"",AH8+AI8),"") | AK8: =IFERROR((($CS8/1.1)-(AG8-(AG8*AF$2)))/($CS8/1.1),"") | AL8: =IFERROR((($CT8/1.1)+(AH8+AI8)-(AG8-(AG8*AF$2)))/($CT8/1.1),"") | AM8: {=IFERROR(_xlfn._xlws.FILTER(ST[SOH],(ST[Code]=$C8) * (ST[Customer Name]=AF$3),"" ),"")} | AN8: {=IFERROR( _xlfn.LET( _xlpm.result, INDEX(_xlfn._xlws.FILTER(ST[6wk avg], (ST[Code]=$C8)*(ST[Customer Name]=AF$3), ""), 1), IF(_xlpm.result=0, "", _xlpm.result) ), "")} | AO8: =IFERROR(IF(CEILING(AN8 + (AN8 * $AO$2), 1) = 0, "", CEILING(AN8 + (AN8 * $AO$2), 1))*$B$3, "") | AP8: =IFERROR((AO8*AH8),"") | AQ8: =IFERROR((AO8*AI8),"") | AS8: {=IFERROR(_xlfn._xlws.FILTER(ST[Customer Code],(ST[Code]=$C8) * (ST[Customer Name]=AS$3),"" ),"")} | AT8: {=IFERROR(_xlfn.XLOOKUP($C8,Query[Code], _xlfn.XLOOKUP('Promo Form'!AS$3,Query[[#Headers],[Code]:[Bing Lee]],Query[[Code]:[Bing Lee]])),"")} | AU8: =IFERROR(((AT8*(1-AS$2))*$CU8)*AS$61,"") | AV8: =IFERROR(((AT8*(1-AS$2))*$CU8)*AS$60,"") | AW8: =IFERROR(IF(AU8+AV8=0,"",AU8+AV8),"") | AX8: =IFERROR((($CS8/1.1)-(AT8-(AT8*AS$2)))/($CS8/1.1),"") | AY8: =IFERROR((($CT8/1.1)+(AU8+AV8)-(AT8-(AT8*AS$2)))/($CT8/1.1),"") | AZ8: {=IFERROR(_xlfn._xlws.FILTER(ST[SOH],(ST[Code]=$C8) * (ST[Customer Name]=AS$3),"" ),"")} | BA8: {=IFERROR( _xlfn.LET( _xlpm.result, INDEX(_xlfn._xlws.FILTER(ST[6wk avg], (ST[Code]=$C8)*(ST[Customer Name]=AS$3), ""), 1), IF(_xlpm.result=0, "", _xlpm.result) ), "")} | BB8: =IFERROR(IF(CEILING(BA8 + (BA8 * $BB$2), 1) = 0, "", CEILING(BA8 + (BA8 * $BB$2), 1))*$B$3, "") | BC8: =IFERROR((BB8*AU8),"") | BD8: =IFERROR((BB8*AV8),"") | BF8: {=IFERROR(_xlfn._xlws.FILTER(ST[Customer Code],(ST[Code]=$C8) * (ST[Customer Name]=BF$3),"" ),"")} | BG8: {=IFERROR(_xlfn.XLOOKUP($C8,Query[Code], _xlfn.XLOOKUP('Promo Form'!BF$3,Query[[#Headers],[Code]:[Bing Lee]],Query[[Code]:[Bing Lee]])),"")} | BH8: =IFERROR(((BG8*(1-BF$2))*$CU8)*BF$61,"") | BI8: =IFERROR(((BG8*(1-BF$2))*$CU8)*BF$60,"") | BJ8: =IFERROR(IF(BH8+BI8=0,"",BH8+BI8),"") | BK8: =IFERROR((($CS8/1.1)-(BG8-(BG8*BF$2)))/($CS8/1.1),"") | BL8: =IFERROR((($CT8/1.1)+(BH8+BI8)-(BG8-(BG8*BF$2)))/($CT8/1.1),"") | BM8: {=IFERROR(_xlfn._xlws.FILTER(ST[SOH],(ST[Code]=$C8) * (ST[Customer Name]=BF$3),"" ),"")} | BN8: {=IFERROR( _xlfn.LET( _xlpm.result, INDEX(_xlfn._xlws.FILTER(ST[6wk avg], (ST[Code]=$C8)*(ST[Customer Name]=BF$3), ""), 1), IF(_xlpm.result=0, "", _xlpm.result) ), "")} | BO8: =IFERROR(IF(CEILING(BN8 + (BN8 * $BO$2), 1) = 0, "", CEILING(BN8 + (BN8 * $BO$2), 1))*$B$3, "") | BP8: =IFERROR((BO8*BH8),"") | BQ8: =IFERROR((BO8*BI8),"") | BS8: {=IFERROR(_xlfn._xlws.FILTER(ST[Customer Code],(ST[Code]=$C8) * (ST[Customer Name]=BS$3),"" ),"")} | BT8: {=IFERROR(_xlfn.XLOOKUP($C8,Query[Code], _xlfn.XLOOKUP('Promo Form'!BS$3,Query[[#Headers],[Code]:[Bing Lee]],Query[[Code]:[Bing Lee]])),"")} | BU8: =IFERROR(((BT8*(1-BS$2))*$CU8)*BS$61,"") | BV8: =IFERROR(((BT8*(1-BS$2))*$CU8)*BS$60,"") | BW8: =IFERROR(IF(BU8+BV8=0,"",BU8+BV8),"") | BX8: =IFERROR((($CS8/1.1)-(BT8-(BT8*BS$2)))/($CS8/1.1),"") | BY8: =IFERROR((($CT8/1.1)+(BU8+BV8)-(BT8-(BT8*BS$2)))/($CT8/1.1),"") | BZ8: {=IFERROR(_xlfn._xlws.FILTER(ST[SOH],(ST[Code]=$C8) * (ST[Customer Name]=BS$3),"" ),"")} | CA8: {=IFERROR( _xlfn.LET( _xlpm.result, INDEX(_xlfn._xlws.FILTER(ST[6wk avg], (ST[Code]=$C8)*(ST[Customer Name]=BS$3), ""), 1), IF(_xlpm.result=0, "", _xlpm.result) ), "")} | CB8: =IFERROR(IF(CEILING(CA8 + (CA8 * $CB$2), 1) = 0, "", CEILING(CA8 + (CA8 * $CB$2), 1))*$B$3, "") | CC8: =IFERROR((CB8*BU8),"") | CD8: =IFERROR((CB8*BV8),"") | CF8: {=IFERROR(_xlfn._xlws.FILTER(ST[Customer Code],(ST[Code]=$C8) * (ST[Customer Name]=CF$3),"" ),"")} | CG8: {=IFERROR(_xlfn.XLOOKUP($C8,Query[Code], _xlfn.XLOOKUP('Promo Form'!CF$3,Query[[#Headers],[Code]:[Bing Lee]],Query[[Code]:[Bing Lee]])),"")} | CH8: =IFERROR(((CG8*(1-CF$2))*$CU8)*CF$61,"") | CI8: =IFERROR(((CG8*(1-CF$2))*$CU8)*CF$60,"") | CJ8: =IFERROR(IF(CH8+CI8=0,"",CH8+CI8),"") | CK8: =IFERROR((($CS8/1.1)-(CG8-(CG8*CF$2)))/($CS8/1.1),"") | CL8: =IFERROR((($CT8/1.1)+(CH8+CI8)-(CG8-(CG8*CF$2)))/($CT8/1.1),"") | CM8: {=IFERROR(_xlfn._xlws.FILTER(ST[SOH],(ST[Code]=$C8) * (ST[Customer Name]=CF$3),"" ),"")} | CN8: {=IFERROR( _xlfn.LET( _xlpm.result, INDEX(_xlfn._xlws.FILTER(ST[6wk avg], (ST[Code]=$C8)*(ST[Customer Name]=CF$3), ""), 1), IF(_xlpm.result=0, "", _xlpm.result) ), "")} | CO8: =IFERROR(IF(CEILING(CN8 + (CN8 * $CO$2), 1) = 0, "", CEILING(CN8 + (CN8 * $CO$2), 1))*$B$3, "") | CP8: =IFERROR((CO8*CH8),"") | CQ8: =IFERROR((CO8*CI8),"") | CS8: =IFERROR(_xlfn.XLOOKUP(C8,Query[Code],Query[Base (RRP Inc)]),"") | CT8: =IFERROR(CS8-(CS8*CU8),"") | CU8: =IF(C8="", "",CU7) | CV8: =IFERROR((CS8-CT8),"")
A9: =IF(C9="","",A8) | B9: =IF(C9="","",B8) | D9: =IF(C9="", "",_xlfn.XLOOKUP(C9,'Master Price Level'!C:C,'Master Price Level'!D:D)) | F9: {=IFERROR(_xlfn._xlws.FILTER(ST[Customer Code],(ST[Code]=$C9) * (ST[Customer Name]=F$3),"" ),"")} | G9: {=IFERROR(_xlfn.XLOOKUP($C9,Query[Code], _xlfn.XLOOKUP('Promo Form'!F$3,Query[[#Headers],[Code]:[Bing Lee]],Query[[Code]:[Bing Lee]])),"")} | H9: =IFERROR(((G9*(1-F$2))*$CU9)*F$61,"") | I9: =IFERROR(((G9*(1-F$2))*$CU9)*F$60,"") | J9: =IFERROR(IF(H9+I9=0,"",H9+I9),"") | K9: =IFERROR((($CS9/1.1)-(G9-(G9*F$2)))/($CS9/1.1),"") | L9: =IFERROR((($CT9/1.1)+(H9+I9)-(G9-(G9*F$2)))/($CT9/1.1),"") | M9: {=IFERROR(_xlfn._xlws.FILTER(ST[SOH],(ST[Code]=$C9) * (ST[Customer Name]=F$3),"" ),"")} | N9: {=IFERROR( _xlfn.LET( _xlpm.result, INDEX(_xlfn._xlws.FILTER(ST[6wk avg], (ST[Code]=$C9)*(ST[Customer Name]=F$3), ""), 1), IF(_xlpm.result=0, "", _xlpm.result) ), "")} | O9: =IFERROR(IF(CEILING(N9 + (N9 * $O$2), 1) = 0, "", CEILING(N9 + (N9 * $O$2), 1))*$B$3, "") | P9: =IFERROR((O9*H9),"") | Q9: =IFERROR((O9*I9),"") | S9: {=IFERROR(_xlfn._xlws.FILTER(ST[Customer Code],(ST[Code]=$C9) * (ST[Customer Name]=S$3),"" ),"")} | T9: {=IFERROR(_xlfn.XLOOKUP($C9,Query[Code], _xlfn.XLOOKUP('Promo Form'!S$3,Query[[#Headers],[Code]:[Bing Lee]],Query[[Code]:[Bing Lee]])),"")} | U9: =IFERROR(((T9*(1-S$2))*$CU9)*S$61,"") | V9: =IFERROR(((T9*(1-S$2))*$CU9)*S$60,"") | W9: =IFERROR(IF(U9+V9=0,"",U9+V9),"") | X9: =IFERROR((($CS9/1.1)-(T9-(T9*S$2)))/($CS9/1.1),"") | Y9: =IFERROR((($CT9/1.1)+(U9+V9)-(T9-(T9*S$2)))/($CT9/1.1),"") | Z9: {=IFERROR(_xlfn._xlws.FILTER(ST[SOH],(ST[Code]=$C9) * (ST[Customer Name]=S$3),"" ),"")} | AA9: {=IFERROR( _xlfn.LET( _xlpm.result, INDEX(_xlfn._xlws.FILTER(ST[6wk avg], (ST[Code]=$C9)*(ST[Customer Name]=S$3), ""), 1), IF(_xlpm.result=0, "", _xlpm.result) ), "")} | AB9: =IFERROR(IF(CEILING(AA9 + (AA9 * $AB$2), 1) = 0, "", CEILING(AA9 + (AA9 * $AB$2), 1))*$B$3, "") | AC9: =IFERROR((AB9*U9),"") | AD9: =IFERROR((AB9*V9),"") | AF9: {=IFERROR(_xlfn._xlws.FILTER(ST[Customer Code],(ST[Code]=$C9) * (ST[Customer Name]=AF$3),"" ),"")} | AG9: {=IFERROR(_xlfn.XLOOKUP($C9,Query[Code], _xlfn.XLOOKUP('Promo Form'!AF$3,Query[[#Headers],[Code]:[Bing Lee]],Query[[Code]:[Bing Lee]])),"")} | AH9: =IFERROR(((AG9*(1-AF$2))*$CU9)*AF$61,"") | AI9: =IFERROR(((AG9*(1-AF$2))*$CU9)*AF$60,"") | AJ9: =IFERROR(IF(AH9+AI9=0,"",AH9+AI9),"") | AK9: =IFERROR((($CS9/1.1)-(AG9-(AG9*AF$2)))/($CS9/1.1),"") | AL9: =IFERROR((($CT9/1.1)+(AH9+AI9)-(AG9-(AG9*AF$2)))/($CT9/1.1),"") | AM9: {=IFERROR(_xlfn._xlws.FILTER(ST[SOH],(ST[Code]=$C9) * (ST[Customer Name]=AF$3),"" ),"")} | AN9: {=IFERROR( _xlfn.LET( _xlpm.result, INDEX(_xlfn._xlws.FILTER(ST[6wk avg], (ST[Code]=$C9)*(ST[Customer Name]=AF$3), ""), 1), IF(_xlpm.result=0, "", _xlpm.result) ), "")} | AO9: =IFERROR(IF(CEILING(AN9 + (AN9 * $AO$2), 1) = 0, "", CEILING(AN9 + (AN9 * $AO$2), 1))*$B$3, "") | AP9: =IFERROR((AO9*AH9),"") | AQ9: =IFERROR((AO9*AI9),"") | AS9: {=IFERROR(_xlfn._xlws.FILTER(ST[Customer Code],(ST[Code]=$C9) * (ST[Customer Name]=AS$3),"" ),"")} | AT9: {=IFERROR(_xlfn.XLOOKUP($C9,Query[Code], _xlfn.XLOOKUP('Promo Form'!AS$3,Query[[#Headers],[Code]:[Bing Lee]],Query[[Code]:[Bing Lee]])),"")} | AU9: =IFERROR(((AT9*(1-AS$2))*$CU9)*AS$61,"") | AV9: =IFERROR(((AT9*(1-AS$2))*$CU9)*AS$60,"") | AW9: =IFERROR(IF(AU9+AV9=0,"",AU9+AV9),"") | AX9: =IFERROR((($CS9/1.1)-(AT9-(AT9*AS$2)))/($CS9/1.1),"") | AY9: =IFERROR((($CT9/1.1)+(AU9+AV9)-(AT9-(AT9*AS$2)))/($CT9/1.1),"") | AZ9: {=IFERROR(_xlfn._xlws.FILTER(ST[SOH],(ST[Code]=$C9) * (ST[Customer Name]=AS$3),"" ),"")} | BA9: {=IFERROR( _xlfn.LET( _xlpm.result, INDEX(_xlfn._xlws.FILTER(ST[6wk avg], (ST[Code]=$C9)*(ST[Customer Name]=AS$3), ""), 1), IF(_xlpm.result=0, "", _xlpm.result) ), "")} | BB9: =IFERROR(IF(CEILING(BA9 + (BA9 * $BB$2), 1) = 0, "", CEILING(BA9 + (BA9 * $BB$2), 1))*$B$3, "") | BC9: =IFERROR((BB9*AU9),"") | BD9: =IFERROR((BB9*AV9),"") | BF9: {=IFERROR(_xlfn._xlws.FILTER(ST[Customer Code],(ST[Code]=$C9) * (ST[Customer Name]=BF$3),"" ),"")} | BG9: {=IFERROR(_xlfn.XLOOKUP($C9,Query[Code], _xlfn.XLOOKUP('Promo Form'!BF$3,Query[[#Headers],[Code]:[Bing Lee]],Query[[Code]:[Bing Lee]])),"")} | BH9: =IFERROR(((BG9*(1-BF$2))*$CU9)*BF$61,"") | BI9: =IFERROR(((BG9*(1-BF$2))*$CU9)*BF$60,"") | BJ9: =IFERROR(IF(BH9+BI9=0,"",BH9+BI9),"") | BK9: =IFERROR((($CS9/1.1)-(BG9-(BG9*BF$2)))/($CS9/1.1),"") | BL9: =IFERROR((($CT9/1.1)+(BH9+BI9)-(BG9-(BG9*BF$2)))/($CT9/1.1),"") | BM9: {=IFERROR(_xlfn._xlws.FILTER(ST[SOH],(ST[Code]=$C9) * (ST[Customer Name]=BF$3),"" ),"")} | BN9: {=IFERROR( _xlfn.LET( _xlpm.result, INDEX(_xlfn._xlws.FILTER(ST[6wk avg], (ST[Code]=$C9)*(ST[Customer Name]=BF$3), ""), 1), IF(_xlpm.result=0, "", _xlpm.result) ), "")} | BO9: =IFERROR(IF(CEILING(BN9 + (BN9 * $BO$2), 1) = 0, "", CEILING(BN9 + (BN9 * $BO$2), 1))*$B$3, "") | BP9: =IFERROR((BO9*BH9),"") | BQ9: =IFERROR((BO9*BI9),"") | BS9: {=IFERROR(_xlfn._xlws.FILTER(ST[Customer Code],(ST[Code]=$C9) * (ST[Customer Name]=BS$3),"" ),"")} | BT9: {=IFERROR(_xlfn.XLOOKUP($C9,Query[Code], _xlfn.XLOOKUP('Promo Form'!BS$3,Query[[#Headers],[Code]:[Bing Lee]],Query[[Code]:[Bing Lee]])),"")} | BU9: =IFERROR(((BT9*(1-BS$2))*$CU9)*BS$61,"") | BV9: =IFERROR(((BT9*(1-BS$2))*$CU9)*BS$60,"") | BW9: =IFERROR(IF(BU9+BV9=0,"",BU9+BV9),"") | BX9: =IFERROR((($CS9/1.1)-(BT9-(BT9*BS$2)))/($CS9/1.1),"") | BY9: =IFERROR((($CT9/1.1)+(BU9+BV9)-(BT9-(BT9*BS$2)))/($CT9/1.1),"") | BZ9: {=IFERROR(_xlfn._xlws.FILTER(ST[SOH],(ST[Code]=$C9) * (ST[Customer Name]=BS$3),"" ),"")} | CA9: {=IFERROR( _xlfn.LET( _xlpm.result, INDEX(_xlfn._xlws.FILTER(ST[6wk avg], (ST[Code]=$C9)*(ST[Customer Name]=BS$3), ""), 1), IF(_xlpm.result=0, "", _xlpm.result) ), "")} | CB9: =IFERROR(IF(CEILING(CA9 + (CA9 * $CB$2), 1) = 0, "", CEILING(CA9 + (CA9 * $CB$2), 1))*$B$3, "") | CC9: =IFERROR((CB9*BU9),"") | CD9: =IFERROR((CB9*BV9),"") | CF9: {=IFERROR(_xlfn._xlws.FILTER(ST[Customer Code],(ST[Code]=$C9) * (ST[Customer Name]=CF$3),"" ),"")} | CG9: {=IFERROR(_xlfn.XLOOKUP($C9,Query[Code], _xlfn.XLOOKUP('Promo Form'!CF$3,Query[[#Headers],[Code]:[Bing Lee]],Query[[Code]:[Bing Lee]])),"")} | CH9: =IFERROR(((CG9*(1-CF$2))*$CU9)*CF$61,"") | CI9: =IFERROR(((CG9*(1-CF$2))*$CU9)*CF$60,"") | CJ9: =IFERROR(IF(CH9+CI9=0,"",CH9+CI9),"") | CK9: =IFERROR((($CS9/1.1)-(CG9-(CG9*CF$2)))/($CS9/1.1),"") | CL9: =IFERROR((($CT9/1.1)+(CH9+CI9)-(CG9-(CG9*CF$2)))/($CT9/1.1),"") | CM9: {=IFERROR(_xlfn._xlws.FILTER(ST[SOH],(ST[Code]=$C9) * (ST[Customer Name]=CF$3),"" ),"")} | CN9: {=IFERROR( _xlfn.LET( _xlpm.result, INDEX(_xlfn._xlws.FILTER(ST[6wk avg], (ST[Code]=$C9)*(ST[Customer Name]=CF$3), ""), 1), IF(_xlpm.result=0, "", _xlpm.result) ), "")} | CO9: =IFERROR(IF(CEILING(CN9 + (CN9 * $CO$2), 1) = 0, "", CEILING(CN9 + (CN9 * $CO$2), 1))*$B$3, "") | CP9: =IFERROR((CO9*CH9),"") | CQ9: =IFERROR((CO9*CI9),"") | CS9: =IFERROR(_xlfn.XLOOKUP(C9,Query[Code],Query[Base (RRP Inc)]),"") | CT9: =IFERROR(CS9-(CS9*CU9),"") | CU9: =IF(C9="", "",CU8) | CV9: =IFERROR((CS9-CT9),"")
A10: =IF(C10="","",A9) | B10: =IF(C10="","",B9) | D10: =IF(C10="", "",_xlfn.XLOOKUP(C10,'Master Price Level'!C:C,'Master Price Level'!D:D)) | F10: {=IFERROR(_xlfn._xlws.FILTER(ST[Customer Code],(ST[Code]=$C10) * (ST[Customer Name]=F$3),"" ),"")} | G10: {=IFERROR(_xlfn.XLOOKUP($C10,Query[Code], _xlfn.XLOOKUP('Promo Form'!F$3,Query[[#Headers],[Code]:[Bing Lee]],Query[[Code]:[Bing Lee]])),"")} | H10: =IFERROR(((G10*(1-F$2))*$CU10)*F$61,"") | I10: =IFERROR(((G10*(1-F$2))*$CU10)*F$60,"") | J10: =IFERROR(IF(H10+I10=0,"",H10+I10),"") | K10: =IFERROR((($CS10/1.1)-(G10-(G10*F$2)))/($CS10/1.1),"") | L10: =IFERROR((($CT10/1.1)+(H10+I10)-(G10-(G10*F$2)))/($CT10/1.1),"") | M10: {=IFERROR(_xlfn._xlws.FILTER(ST[SOH],(ST[Code]=$C10) * (ST[Customer Name]=F$3),"" ),"")} | N10: {=IFERROR( _xlfn.LET( _xlpm.result, INDEX(_xlfn._xlws.FILTER(ST[6wk avg], (ST[Code]=$C10)*(ST[Customer Name]=F$3), ""), 1), IF(_xlpm.result=0, "", _xlpm.result) ), "")} | O10: =IFERROR(IF(CEILING(N10 + (N10 * $O$2), 1) = 0, "", CEILING(N10 + (N10 * $O$2), 1))*$B$3, "") | P10: =IFERROR((O10*H10),"") | Q10: =IFERROR((O10*I10),"") | S10: {=IFERROR(_xlfn._xlws.FILTER(ST[Customer Code],(ST[Code]=$C10) * (ST[Customer Name]=S$3),"" ),"")} | T10: {=IFERROR(_xlfn.XLOOKUP($C10,Query[Code], _xlfn.XLOOKUP('Promo Form'!S$3,Query[[#Headers],[Code]:[Bing Lee]],Query[[Code]:[Bing Lee]])),"")} | U10: =IFERROR(((T10*(1-S$2))*$CU10)*S$61,"") | V10: =IFERROR(((T10*(1-S$2))*$CU10)*S$60,"") | W10: =IFERROR(IF(U10+V10=0,"",U10+V10),"") | X10: =IFERROR((($CS10/1.1)-(T10-(T10*S$2)))/($CS10/1.1),"") | Y10: =IFERROR((($CT10/1.1)+(U10+V10)-(T10-(T10*S$2)))/($CT10/1.1),"") | Z10: {=IFERROR(_xlfn._xlws.FILTER(ST[SOH],(ST[Code]=$C10) * (ST[Customer Name]=S$3),"" ),"")} | AA10: {=IFERROR( _xlfn.LET( _xlpm.result, INDEX(_xlfn._xlws.FILTER(ST[6wk avg], (ST[Code]=$C10)*(ST[Customer Name]=S$3), ""), 1), IF(_xlpm.result=0, "", _xlpm.result) ), "")} | AB10: =IFERROR(IF(CEILING(AA10 + (AA10 * $AB$2), 1) = 0, "", CEILING(AA10 + (AA10 * $AB$2), 1))*$B$3, "") | AC10: =IFERROR((AB10*U10),"") | AD10: =IFERROR((AB10*V10),"") | AF10: {=IFERROR(_xlfn._xlws.FILTER(ST[Customer Code],(ST[Code]=$C10) * (ST[Customer Name]=AF$3),"" ),"")} | AG10: {=IFERROR(_xlfn.XLOOKUP($C10,Query[Code], _xlfn.XLOOKUP('Promo Form'!AF$3,Query[[#Headers],[Code]:[Bing Lee]],Query[[Code]:[Bing Lee]])),"")} | AH10: =IFERROR(((AG10*(1-AF$2))*$CU10)*AF$61,"") | AI10: =IFERROR(((AG10*(1-AF$2))*$CU10)*AF$60,"") | AJ10: =IFERROR(IF(AH10+AI10=0,"",AH10+AI10),"") | AK10: =IFERROR((($CS10/1.1)-(AG10-(AG10*AF$2)))/($CS10/1.1),"") | AL10: =IFERROR((($CT10/1.1)+(AH10+AI10)-(AG10-(AG10*AF$2)))/($CT10/1.1),"") | AM10: {=IFERROR(_xlfn._xlws.FILTER(ST[SOH],(ST[Code]=$C10) * (ST[Customer Name]=AF$3),"" ),"")} | AN10: {=IFERROR( _xlfn.LET( _xlpm.result, INDEX(_xlfn._xlws.FILTER(ST[6wk avg], (ST[Code]=$C10)*(ST[Customer Name]=AF$3), ""), 1), IF(_xlpm.result=0, "", _xlpm.result) ), "")} | AO10: =IFERROR(IF(CEILING(AN10 + (AN10 * $AO$2), 1) = 0, "", CEILING(AN10 + (AN10 * $AO$2), 1))*$B$3, "") | AP10: =IFERROR((AO10*AH10),"") | AQ10: =IFERROR((AO10*AI10),"") | AS10: {=IFERROR(_xlfn._xlws.FILTER(ST[Customer Code],(ST[Code]=$C10) * (ST[Customer Name]=AS$3),"" ),"")} | AT10: {=IFERROR(_xlfn.XLOOKUP($C10,Query[Code], _xlfn.XLOOKUP('Promo Form'!AS$3,Query[[#Headers],[Code]:[Bing Lee]],Query[[Code]:[Bing Lee]])),"")} | AU10: =IFERROR(((AT10*(1-AS$2))*$CU10)*AS$61,"") | AV10: =IFERROR(((AT10*(1-AS$2))*$CU10)*AS$60,"") | AW10: =IFERROR(IF(AU10+AV10=0,"",AU10+AV10),"") | AX10: =IFERROR((($CS10/1.1)-(AT10-(AT10*AS$2)))/($CS10/1.1),"") | AY10: =IFERROR((($CT10/1.1)+(AU10+AV10)-(AT10-(AT10*AS$2)))/($CT10/1.1),"") | AZ10: {=IFERROR(_xlfn._xlws.FILTER(ST[SOH],(ST[Code]=$C10) * (ST[Customer Name]=AS$3),"" ),"")} | BA10: {=IFERROR( _xlfn.LET( _xlpm.result, INDEX(_xlfn._xlws.FILTER(ST[6wk avg], (ST[Code]=$C10)*(ST[Customer Name]=AS$3), ""), 1), IF(_xlpm.result=0, "", _xlpm.result) ), "")} | BB10: =IFERROR(IF(CEILING(BA10 + (BA10 * $BB$2), 1) = 0, "", CEILING(BA10 + (BA10 * $BB$2), 1))*$B$3, "") | BC10: =IFERROR((BB10*AU10),"") | BD10: =IFERROR((BB10*AV10),"") | BF10: {=IFERROR(_xlfn._xlws.FILTER(ST[Customer Code],(ST[Code]=$C10) * (ST[Customer Name]=BF$3),"" ),"")} | BG10: {=IFERROR(_xlfn.XLOOKUP($C10,Query[Code], _xlfn.XLOOKUP('Promo Form'!BF$3,Query[[#Headers],[Code]:[Bing Lee]],Query[[Code]:[Bing Lee]])),"")} | BH10: =IFERROR(((BG10*(1-BF$2))*$CU10)*BF$61,"") | BI10: =IFERROR(((BG10*(1-BF$2))*$CU10)*BF$60,"") | BJ10: =IFERROR(IF(BH10+BI10=0,"",BH10+BI10),"") | BK10: =IFERROR((($CS10/1.1)-(BG10-(BG10*BF$2)))/($CS10/1.1),"") | BL10: =IFERROR((($CT10/1.1)+(BH10+BI10)-(BG10-(BG10*BF$2)))/($CT10/1.1),"") | BM10: {=IFERROR(_xlfn._xlws.FILTER(ST[SOH],(ST[Code]=$C10) * (ST[Customer Name]=BF$3),"" ),"")} | BN10: {=IFERROR( _xlfn.LET( _xlpm.result, INDEX(_xlfn._xlws.FILTER(ST[6wk avg], (ST[Code]=$C10)*(ST[Customer Name]=BF$3), ""), 1), IF(_xlpm.result=0, "", _xlpm.result) ), "")} | BO10: =IFERROR(IF(CEILING(BN10 + (BN10 * $BO$2), 1) = 0, "", CEILING(BN10 + (BN10 * $BO$2), 1))*$B$3, "") | BP10: =IFERROR((BO10*BH10),"") | BQ10: =IFERROR((BO10*BI10),"") | BS10: {=IFERROR(_xlfn._xlws.FILTER(ST[Customer Code],(ST[Code]=$C10) * (ST[Customer Name]=BS$3),"" ),"")} | BT10: {=IFERROR(_xlfn.XLOOKUP($C10,Query[Code], _xlfn.XLOOKUP('Promo Form'!BS$3,Query[[#Headers],[Code]:[Bing Lee]],Query[[Code]:[Bing Lee]])),"")} | BU10: =IFERROR(((BT10*(1-BS$2))*$CU10)*BS$61,"") | BV10: =IFERROR(((BT10*(1-BS$2))*$CU10)*BS$60,"") | BW10: =IFERROR(IF(BU10+BV10=0,"",BU10+BV10),"") | BX10: =IFERROR((($CS10/1.1)-(BT10-(BT10*BS$2)))/($CS10/1.1),"") | BY10: =IFERROR((($CT10/1.1)+(BU10+BV10)-(BT10-(BT10*BS$2)))/($CT10/1.1),"") | BZ10: {=IFERROR(_xlfn._xlws.FILTER(ST[SOH],(ST[Code]=$C10) * (ST[Customer Name]=BS$3),"" ),"")} | CA10: {=IFERROR( _xlfn.LET( _xlpm.result, INDEX(_xlfn._xlws.FILTER(ST[6wk avg], (ST[Code]=$C10)*(ST[Customer Name]=BS$3), ""), 1), IF(_xlpm.result=0, "", _xlpm.result) ), "")} | CB10: =IFERROR(IF(CEILING(CA10 + (CA10 * $CB$2), 1) = 0, "", CEILING(CA10 + (CA10 * $CB$2), 1))*$B$3, "") | CC10: =IFERROR((CB10*BU10),"") | CD10: =IFERROR((CB10*BV10),"") | CF10: {=IFERROR(_xlfn._xlws.FILTER(ST[Customer Code],(ST[Code]=$C10) * (ST[Customer Name]=CF$3),"" ),"")} | CG10: {=IFERROR(_xlfn.XLOOKUP($C10,Query[Code], _xlfn.XLOOKUP('Promo Form'!CF$3,Query[[#Headers],[Code]:[Bing Lee]],Query[[Code]:[Bing Lee]])),"")} | CH10: =IFERROR(((CG10*(1-CF$2))*$CU10)*CF$61,"") | CI10: =IFERROR(((CG10*(1-CF$2))*$CU10)*CF$60,"") | CJ10: =IFERROR(IF(CH10+CI10=0,"",CH10+CI10),"") | CK10: =IFERROR((($CS10/1.1)-(CG10-(CG10*CF$2)))/($CS10/1.1),"") | CL10: =IFERROR((($CT10/1.1)+(CH10+CI10)-(CG10-(CG10*CF$2)))/($CT10/1.1),"") | CM10: {=IFERROR(_xlfn._xlws.FILTER(ST[SOH],(ST[Code]=$C10) * (ST[Customer Name]=CF$3),"" ),"")} | CN10: {=IFERROR( _xlfn.LET( _xlpm.result, INDEX(_xlfn._xlws.FILTER(ST[6wk avg], (ST[Code]=$C10)*(ST[Customer Name]=CF$3), ""), 1), IF(_xlpm.result=0, "", _xlpm.result) ), "")} | CO10: =IFERROR(IF(CEILING(CN10 + (CN10 * $CO$2), 1) = 0, "", CEILING(CN10 + (CN10 * $CO$2), 1))*$B$3, "") | CP10: =IFERROR((CO10*CH10),"") | CQ10: =IFERROR((CO10*CI10),"") | CS10: =IFERROR(_xlfn.XLOOKUP(C10,Query[Code],Query[Base (RRP Inc)]),"") | CT10: =IFERROR(CS10-(CS10*CU10),"") | CU10: =IF(C10="", "",CU9) | CV10: =IFERROR((CS10-CT10),"")
A11: =IF(C11="","",A10) | B11: =IF(C11="","",B10) | D11: =IF(C11="", "",_xlfn.XLOOKUP(C11,'Master Price Level'!C:C,'Master Price Level'!D:D)) | F11: {=IFERROR(_xlfn._xlws.FILTER(ST[Customer Code],(ST[Code]=$C11) * (ST[Customer Name]=F$3),"" ),"")} | G11: {=IFERROR(_xlfn.XLOOKUP($C11,Query[Code], _xlfn.XLOOKUP('Promo Form'!F$3,Query[[#Headers],[Code]:[Bing Lee]],Query[[Code]:[Bing Lee]])),"")} | H11: =IFERROR(((G11*(1-F$2))*$CU11)*F$61,"") | I11: =IFERROR(((G11*(1-F$2))*$CU11)*F$60,"") | J11: =IFERROR(IF(H11+I11=0,"",H11+I11),"") | K11: =IFERROR((($CS11/1.1)-(G11-(G11*F$2)))/($CS11/1.1),"") | L11: =IFERROR((($CT11/1.1)+(H11+I11)-(G11-(G11*F$2)))/($CT11/1.1),"") | M11: {=IFERROR(_xlfn._xlws.FILTER(ST[SOH],(ST[Code]=$C11) * (ST[Customer Name]=F$3),"" ),"")} | N11: {=IFERROR( _xlfn.LET( _xlpm.result, INDEX(_xlfn._xlws.FILTER(ST[6wk avg], (ST[Code]=$C11)*(ST[Customer Name]=F$3), ""), 1), IF(_xlpm.result=0, "", _xlpm.result) ), "")} | O11: =IFERROR(IF(CEILING(N11 + (N11 * $O$2), 1) = 0, "", CEILING(N11 + (N11 * $O$2), 1))*$B$3, "") | P11: =IFERROR((O11*H11),"") | Q11: =IFERROR((O11*I11),"") | S11: {=IFERROR(_xlfn._xlws.FILTER(ST[Customer Code],(ST[Code]=$C11) * (ST[Customer Name]=S$3),"" ),"")} | T11: {=IFERROR(_xlfn.XLOOKUP($C11,Query[Code], _xlfn.XLOOKUP('Promo Form'!S$3,Query[[#Headers],[Code]:[Bing Lee]],Query[[Code]:[Bing Lee]])),"")} | U11: =IFERROR(((T11*(1-S$2))*$CU11)*S$61,"") | V11: =IFERROR(((T11*(1-S$2))*$CU11)*S$60,"") | W11: =IFERROR(IF(U11+V11=0,"",U11+V11),"") | X11: =IFERROR((($CS11/1.1)-(T11-(T11*S$2)))/($CS11/1.1),"") | Y11: =IFERROR((($CT11/1.1)+(U11+V11)-(T11-(T11*S$2)))/($CT11/1.1),"") | Z11: {=IFERROR(_xlfn._xlws.FILTER(ST[SOH],(ST[Code]=$C11) * (ST[Customer Name]=S$3),"" ),"")} | AA11: {=IFERROR( _xlfn.LET( _xlpm.result, INDEX(_xlfn._xlws.FILTER(ST[6wk avg], (ST[Code]=$C11)*(ST[Customer Name]=S$3), ""), 1), IF(_xlpm.result=0, "", _xlpm.result) ), "")} | AB11: =IFERROR(IF(CEILING(AA11 + (AA11 * $AB$2), 1) = 0, "", CEILING(AA11 + (AA11 * $AB$2), 1))*$B$3, "") | AC11: =IFERROR((AB11*U11),"") | AD11: =IFERROR((AB11*V11),"") | AF11: {=IFERROR(_xlfn._xlws.FILTER(ST[Customer Code],(ST[Code]=$C11) * (ST[Customer Name]=AF$3),"" ),"")} | AG11: {=IFERROR(_xlfn.XLOOKUP($C11,Query[Code], _xlfn.XLOOKUP('Promo Form'!AF$3,Query[[#Headers],[Code]:[Bing Lee]],Query[[Code]:[Bing Lee]])),"")} | AH11: =IFERROR(((AG11*(1-AF$2))*$CU11)*AF$61,"") | AI11: =IFERROR(((AG11*(1-AF$2))*$CU11)*AF$60,"") | AJ11: =IFERROR(IF(AH11+AI11=0,"",AH11+AI11),"") | AK11: =IFERROR((($CS11/1.1)-(AG11-(AG11*AF$2)))/($CS11/1.1),"") | AL11: =IFERROR((($CT11/1.1)+(AH11+AI11)-(AG11-(AG11*AF$2)))/($CT11/1.1),"") | AM11: {=IFERROR(_xlfn._xlws.FILTER(ST[SOH],(ST[Code]=$C11) * (ST[Customer Name]=AF$3),"" ),"")} | AN11: {=IFERROR( _xlfn.LET( _xlpm.result, INDEX(_xlfn._xlws.FILTER(ST[6wk avg], (ST[Code]=$C11)*(ST[Customer Name]=AF$3), ""), 1), IF(_xlpm.result=0, "", _xlpm.result) ), "")} | AO11: =IFERROR(IF(CEILING(AN11 + (AN11 * $AO$2), 1) = 0, "", CEILING(AN11 + (AN11 * $AO$2), 1))*$B$3, "") | AP11: =IFERROR((AO11*AH11),"") | AQ11: =IFERROR((AO11*AI11),"") | AS11: {=IFERROR(_xlfn._xlws.FILTER(ST[Customer Code],(ST[Code]=$C11) * (ST[Customer Name]=AS$3),"" ),"")} | AT11: {=IFERROR(_xlfn.XLOOKUP($C11,Query[Code], _xlfn.XLOOKUP('Promo Form'!AS$3,Query[[#Headers],[Code]:[Bing Lee]],Query[[Code]:[Bing Lee]])),"")} | AU11: =IFERROR(((AT11*(1-AS$2))*$CU11)*AS$61,"") | AV11: =IFERROR(((AT11*(1-AS$2))*$CU11)*AS$60,"") | AW11: =IFERROR(IF(AU11+AV11=0,"",AU11+AV11),"") | AX11: =IFERROR((($CS11/1.1)-(AT11-(AT11*AS$2)))/($CS11/1.1),"") | AY11: =IFERROR((($CT11/1.1)+(AU11+AV11)-(AT11-(AT11*AS$2)))/($CT11/1.1),"") | AZ11: {=IFERROR(_xlfn._xlws.FILTER(ST[SOH],(ST[Code]=$C11) * (ST[Customer Name]=AS$3),"" ),"")} | BA11: {=IFERROR( _xlfn.LET( _xlpm.result, INDEX(_xlfn._xlws.FILTER(ST[6wk avg], (ST[Code]=$C11)*(ST[Customer Name]=AS$3), ""), 1), IF(_xlpm.result=0, "", _xlpm.result) ), "")} | BB11: =IFERROR(IF(CEILING(BA11 + (BA11 * $BB$2), 1) = 0, "", CEILING(BA11 + (BA11 * $BB$2), 1))*$B$3, "") | BC11: =IFERROR((BB11*AU11),"") | BD11: =IFERROR((BB11*AV11),"") | BF11: {=IFERROR(_xlfn._xlws.FILTER(ST[Customer Code],(ST[Code]=$C11) * (ST[Customer Name]=BF$3),"" ),"")} | BG11: {=IFERROR(_xlfn.XLOOKUP($C11,Query[Code], _xlfn.XLOOKUP('Promo Form'!BF$3,Query[[#Headers],[Code]:[Bing Lee]],Query[[Code]:[Bing Lee]])),"")} | BH11: =IFERROR(((BG11*(1-BF$2))*$CU11)*BF$61,"") | BI11: =IFERROR(((BG11*(1-BF$2))*$CU11)*BF$60,"") | BJ11: =IFERROR(IF(BH11+BI11=0,"",BH11+BI11),"") | BK11: =IFERROR((($CS11/1.1)-(BG11-(BG11*BF$2)))/($CS11/1.1),"") | BL11: =IFERROR((($CT11/1.1)+(BH11+BI11)-(BG11-(BG11*BF$2)))/($CT11/1.1),"") | BM11: {=IFERROR(_xlfn._xlws.FILTER(ST[SOH],(ST[Code]=$C11) * (ST[Customer Name]=BF$3),"" ),"")} | BN11: {=IFERROR( _xlfn.LET( _xlpm.result, INDEX(_xlfn._xlws.FILTER(ST[6wk avg], (ST[Code]=$C11)*(ST[Customer Name]=BF$3), ""), 1), IF(_xlpm.result=0, "", _xlpm.result) ), "")} | BO11: =IFERROR(IF(CEILING(BN11 + (BN11 * $BO$2), 1) = 0, "", CEILING(BN11 + (BN11 * $BO$2), 1))*$B$3, "") | BP11: =IFERROR((BO11*BH11),"") | BQ11: =IFERROR((BO11*BI11),"") | BS11: {=IFERROR(_xlfn._xlws.FILTER(ST[Customer Code],(ST[Code]=$C11) * (ST[Customer Name]=BS$3),"" ),"")} | BT11: {=IFERROR(_xlfn.XLOOKUP($C11,Query[Code], _xlfn.XLOOKUP('Promo Form'!BS$3,Query[[#Headers],[Code]:[Bing Lee]],Query[[Code]:[Bing Lee]])),"")} | BU11: =IFERROR(((BT11*(1-BS$2))*$CU11)*BS$61,"") | BV11: =IFERROR(((BT11*(1-BS$2))*$CU11)*BS$60,"") | BW11: =IFERROR(IF(BU11+BV11=0,"",BU11+BV11),"") | BX11: =IFERROR((($CS11/1.1)-(BT11-(BT11*BS$2)))/($CS11/1.1),"") | BY11: =IFERROR((($CT11/1.1)+(BU11+BV11)-(BT11-(BT11*BS$2)))/($CT11/1.1),"") | BZ11: {=IFERROR(_xlfn._xlws.FILTER(ST[SOH],(ST[Code]=$C11) * (ST[Customer Name]=BS$3),"" ),"")} | CA11: {=IFERROR( _xlfn.LET( _xlpm.result, INDEX(_xlfn._xlws.FILTER(ST[6wk avg], (ST[Code]=$C11)*(ST[Customer Name]=BS$3), ""), 1), IF(_xlpm.result=0, "", _xlpm.result) ), "")} | CB11: =IFERROR(IF(CEILING(CA11 + (CA11 * $CB$2), 1) = 0, "", CEILING(CA11 + (CA11 * $CB$2), 1))*$B$3, "") | CC11: =IFERROR((CB11*BU11),"") | CD11: =IFERROR((CB11*BV11),"") | CF11: {=IFERROR(_xlfn._xlws.FILTER(ST[Customer Code],(ST[Code]=$C11) * (ST[Customer Name]=CF$3),"" ),"")} | CG11: {=IFERROR(_xlfn.XLOOKUP($C11,Query[Code], _xlfn.XLOOKUP('Promo Form'!CF$3,Query[[#Headers],[Code]:[Bing Lee]],Query[[Code]:[Bing Lee]])),"")} | CH11: =IFERROR(((CG11*(1-CF$2))*$CU11)*CF$61,"") | CI11: =IFERROR(((CG11*(1-CF$2))*$CU11)*CF$60,"") | CJ11: =IFERROR(IF(CH11+CI11=0,"",CH11+CI11),"") | CK11: =IFERROR((($CS11/1.1)-(CG11-(CG11*CF$2)))/($CS11/1.1),"") | CL11: =IFERROR((($CT11/1.1)+(CH11+CI11)-(CG11-(CG11*CF$2)))/($CT11/1.1),"") | CM11: {=IFERROR(_xlfn._xlws.FILTER(ST[SOH],(ST[Code]=$C11) * (ST[Customer Name]=CF$3),"" ),"")} | CN11: {=IFERROR( _xlfn.LET( _xlpm.result, INDEX(_xlfn._xlws.FILTER(ST[6wk avg], (ST[Code]=$C11)*(ST[Customer Name]=CF$3), ""), 1), IF(_xlpm.result=0, "", _xlpm.result) ), "")} | CO11: =IFERROR(IF(CEILING(CN11 + (CN11 * $CO$2), 1) = 0, "", CEILING(CN11 + (CN11 * $CO$2), 1))*$B$3, "") | CP11: =IFERROR((CO11*CH11),"") | CQ11: =IFERROR((CO11*CI11),"") | CS11: =IFERROR(_xlfn.XLOOKUP(C11,Query[Code],Query[Base (RRP Inc)]),"") | CT11: =IFERROR(CS11-(CS11*CU11),"") | CU11: =IF(C11="", "",CU10) | CV11: =IFERROR((CS11-CT11),"")
