Workbook

Sheet Promo Form
A1: New Zealand Claim Number | D1: Name of Promotion. | F1: Rebate | G1: 6 | R1: Rebate | S1: 6 | AD1: Rebate | AE1: 6 | AP1: Rebate | AQ1: 6 | BB1: Rebate | BC1: 6 | BN1: Rebate | BO1: 6 | BZ1: Rebate | CA1: 6
A2: Brand | F2: 0.24 | M2: Growth | N2: 0.2 | R2: =_xlfn.XLOOKUP(R$3,'Data Validation'!$A:$A,'Data Validation'!$B:$B) -> 0.203 | T2: JB HIFI | Y2: Growth | Z2: 0.2 | AD2: =_xlfn.XLOOKUP(AD$3,'Data Validation'!$A:$A,'Data Validation'!$B:$B) -> 0.17 | AK2: Growth | AL2: 0.2 | AP2: =_xlfn.XLOOKUP(AP$3,'Data Validation'!$A:$A,'Data Validation'!$B:$B) -> 0.05 | AW2: Growth | AX2: 0.2 | BB2: =_xlfn.XLOOKUP(BB$3,'Data Validation'!$A:$A,'Data Validation'!$B:$B) -> 0 | BI2: Growth | BJ2: 0.2 | BN2: =_xlfn.XLOOKUP(BN$3,'Data Validation'!$A:$A,'Data Validation'!$B:$B) -> 0 | BU2: Growth | BV2: 0.2 | BZ2: =_xlfn.XLOOKUP(BZ$3,'Data Validation'!$A:$A,'Data Validation'!$B:$B) -> 0 | CG2: Growth | CH2: 0.2
A3: Promo Date(s) | B3: =(B5-A5)/7 -> 2 | C3: Code | D3: Product Description | F3: Harvey Norman | G3: <-- Select | J3: =F3 -> Harvey Norman | R3: JB HIFI | S3: <-- Select | V3: =R3 -> JB HIFI | AD3: Harvey Norman | AE3: <-- Select | AH3: =AD3 -> Harvey Norman | AP3: PB Tech | AQ3: <-- Select | AT3: =AP3 -> PB Tech | BB3: Spare | BC3: <-- Select | BF3: =BB3 -> Spare | BN3: Spare | BO3: <-- Select | BR3: =BN3 -> Spare | BZ3: Spare | CA3: <-- Select | CD3: =BZ3 -> Spare
A4: From | B4: To | F4: Customer Code | G4: Retailer Buy ex | H4: Supplier Support | I4: MG Support | J4: Total Support | K4: End to End Standard Margin | L4: End to End Promo Margin | M4: 6wk Avg | N4: Expected Sales / Actual Sales | O4: Supplier Claim Amount | P4: MacGear Claim Amount | R4: Customer Code | S4: Retailer Buy ex | T4: Supplier Support | U4: MG Support | V4: Total Support | W4: End to End Standard Margin | X4: End to End Promo Margin | Y4: 6wk Avg | Z4: Expected Sales / Actual Sales | AA4: Supplier Claim Amount | AB4: MacGear Claim Amount | AD4: Customer Code | AE4: Retailer Buy ex | AF4: Supplier Support | AG4: MG Support | AH4: Total Support | AI4: End to End Standard Margin | AJ4: End to End Promo Margin | AK4: 6wk Avg | AL4: Expected Sales / Actual Sales | AM4: Supplier Claim Amount | AN4: MacGear Claim Amount | AP4: Customer Code | AQ4: Retailer Buy ex | AR4: Supplier Support | AS4: MG Support | AT4: Total Support | AU4: End to End Standard Margin | AV4: End to End Promo Margin | AW4: 6wk Avg | AX4: Expected Sales / Actual Sales | AY4: Supplier Claim Amount | AZ4: MacGear Claim Amount | BB4: Customer Code | BC4: Retailer Buy ex | BD4: Supplier Support | BE4: MG Support | BF4: Total Support | BG4: End to End Standard Margin | BH4: End to End Promo Margin | BI4: 6wk Avg | BJ4: Expected Sales / Actual Sales | BK4: Supplier Claim Amount | BL4: MacGear Claim Amount | BN4: Customer Code | BO4: Retailer Buy ex | BP4: Supplier Support | BQ4: MG Support | BR4: Total Support | BS4: End to End Standard Margin | BT4: End to End Promo Margin | BU4: 6wk Avg | BV4: Expected Sales / Actual Sales | BW4: Supplier Claim Amount | BX4: MacGear Claim Amount | BZ4: Customer Code | CA4: Retailer Buy ex | CB4: Supplier Support | CC4: MG Support | CD4: Total Support | CE4: End to End Standard Margin | CF4: End to End Promo Margin | CG4: 6wk Avg | CH4: Expected Sales / Actual Sales | CI4: Supplier Claim Amount | CJ4: MacGear Claim Amount | CL4: RRP Inc | CM4: Recommended Sale Inc | CN4: Recommended % Off | CO4: Recommended $ Off | CP4: Comments
A5: 45658 | B5: 45672 | C5: ADM4DG | D5: =IF(C5="", "",_xlfn.XLOOKUP(C5,'Master Price Level NZ'!B:B,'Master Price Level NZ'!C:C)) -> ADONIT Mini 4 (Grey) | G5: {=IFERROR(_xlfn.XLOOKUP($C5,Master_Price_Level_NZ[Code],INDEX(Master_Price_Level_NZ[], , MATCH('Promo Form'!F$3, Master_Price_Level_NZ[#Headers], 0))),"")} -> 24.34 | H5: =IFERROR(((G5)*$CN5)*F$39,"") -> 1.217 | I5: =IFERROR(((G5)*$CN5)*F$38,"") -> 1.217 | J5: =IFERROR(IF(H5+I5=0,"",H5+I5),"") -> 2.434 | K5: =IFERROR((($CL5/1.15)-(G5-(G5*F$2)))/($CL5/1.15),"") -> 0.46803801 | L5: =IFERROR((($CM5/1.15)+(H5+I5)-(G5-(G5*F$2)))/($CM5/1.15),"") -> 0.42254126 | M5: {=IFERROR( _xlfn.LET( _xlpm.result, INDEX(_xlfn._xlws.FILTER(ST[6wk avg], (ST[Code]=$C5)*(ST[Customer Name]=F$3), ""), 1), IF(_xlpm.result=0, "", _xlpm.result) ), "")} -> 7.5 | N5: =IFERROR(IF(CEILING(M5 + (M5 * $N$2), 1) = 0, "", CEILING(M5 + (M5 * $N$2), 1))*$B$3, "") -> 18 | O5: =IFERROR((N5*H5),"") -> 21.906 | P5: =IFERROR((N5*I5),"") -> 21.906 | R5: {=IFERROR(_xlfn._xlws.FILTER(#REF!,(#REF!=$C5) * (#REF!=R$3),"" ),"")} | S5: {=IFERROR(_xlfn.XLOOKUP($C5,Master_Price_Level_NZ[Code],INDEX(Master_Price_Level_NZ[], , MATCH('Promo Form'!R$3, Master_Price_Level_NZ[#Headers], 0))),"")} -> 24.34 | T5: =IFERROR(((S5)*$CN5)*R$39,"") -> 1.217 | U5: =IFERROR(((S5)*$CN5)*R$38,"") -> 1.217 | V5: =IFERROR(IF(T5+U5=0,"",T5+U5),"") -> 2.434 | W5: =IFERROR((($CL5/1.15)-(S5-(S5*R$2)))/($CL5/1.15),"") -> 0.44213986 | X5: =IFERROR((($CM5/1.15)+(T5+U5)-(S5-(S5*R$2)))/($CM5/1.15),"") -> 0.39016857 | Y5: {=IFERROR( _xlfn.LET( _xlpm.result, INDEX(_xlfn._xlws.FILTER(ST[6wk avg], (ST[Code]=$C5)*(ST[Customer Name]=R$3), ""), 1), IF(_xlpm.result=0, "", _xlpm.result) ), "")} | Z5: =IFERROR(IF(CEILING(Y5 + (Y5 * $Z$2), 1) = 0, "", CEILING(Y5 + (Y5 * $Z$2), 1))*$B$3, "") | AA5: =IFERROR((Z5*T5),"") | AB5: =IFERROR((Z5*U5),"") | AD5: {=IFERROR(_xlfn._xlws.FILTER(#REF!,(#REF!=$C5) * (#REF!=AD$3),"" ),"")} | AE5: {=IFERROR(_xlfn.XLOOKUP($C5,Master_Price_Level_NZ[Code],INDEX(Master_Price_Level_NZ[], , MATCH('Promo Form'!AD$3, Master_Price_Level_NZ[#Headers], 0))),"")} -> 24.34 | AF5: =IFERROR(((AE5)*$CN5)*AD$39,"") -> 1.217 | AG5: =IFERROR(((AE5)*$CN5)*AD$38,"") -> 1.217 | AH5: =IFERROR(IF(AF5+AG5=0,"",AF5+AG5),"") -> 2.434 | AI5: =IFERROR((($CL5/1.15)-(AE5-(AE5*AD$2)))/($CL5/1.15),"") -> 0.41904151 | AJ5: =IFERROR((($CM5/1.15)+(AF5+AG5)-(AE5-(AE5*AD$2)))/($CM5/1.15),"") -> 0.36129564 | AK5: {=IFERROR( _xlfn.LET( _xlpm.result, INDEX(_xlfn._xlws.FILTER(ST[6wk avg], (ST[Code]=$C5)*(ST[Customer Name]=AD$3), ""), 1), IF(_xlpm.result=0, "", _xlpm.result) ), "")} -> 7.5 | AL5: =IFERROR(IF(CEILING(AK5 + (AK5 * $AL$2), 1) = 0, "", CEILING(AK5 + (AK5 * $AL$2), 1))*$B$3, "") -> 18 | AM5: =IFERROR((AL5*AF5),"") -> 21.906 | AN5: =IFERROR((AL5*AG5),"") -> 21.906 | AP5: {=IFERROR(_xlfn._xlws.FILTER(#REF!,(#REF!=$C5) * (#REF!=AP$3),"" ),"")} | AQ5: {=IFERROR(_xlfn.XLOOKUP($C5,Master_Price_Level_NZ[Code],INDEX(Master_Price_Level_NZ[], , MATCH('Promo Form'!AP$3, Master_Price_Level_NZ[#Headers], 0))),"")} -> 20.86 | AR5: =IFERROR(((AQ5)*$CN5)*AP$39,"") -> 1.043 | AS5: =IFERROR(((AQ5)*$CN5)*AP$38,"") -> 1.043 | AT5: =IFERROR(IF(AR5+AS5=0,"",AR5+AS5),"") -> 2.086 | AU5: =IFERROR((($CL5/1.15)-(AQ5-(AQ5*AP$2)))/($CL5/1.15),"") -> 0.43011878 | AV5: =IFERROR((($CM5/1.15)+(AR5+AS5)-(AQ5-(AQ5*AP$2)))/($CM5/1.15),"") -> 0.36263285 | AW5: {=IFERROR( _xlfn.LET( _xlpm.result, INDEX(_xlfn._xlws.FILTER(ST[6wk avg], (ST[Code]=$C5)*(ST[Customer Name]=AP$3), ""), 1), IF(_xlpm.result=0, "", _xlpm.result) ), "")} -> 18.5 | AX5: =IFERROR(IF(CEILING(AW5 + (AW5 * $AX$2), 1) = 0, "", CEILING(AW5 + (AW5 * $AX$2), 1))*$B$3, "") -> 46 | AY5: =IFERROR((AX5*AR5),"") -> 47.978 | AZ5: =IFERROR((AX5*AS5),"") -> 47.978 | BB5: {=IFERROR(_xlfn._xlws.FILTER(#REF!,(#REF!=$C5) * (#REF!=BB$3),"" ),"")} | BC5: {=IFERROR(_xlfn.XLOOKUP($C5,Master_Price_Level_NZ[Code],INDEX(Master_Price_Level_NZ[], , MATCH('Promo Form'!BB$3, Master_Price_Level_NZ[#Headers], 0))),"")} | BD5: =IFERROR(((BC5)*$CN5)*BB$39,"") | BE5: =IFERROR(((BC5)*$CN5)*BB$38,"") | BF5: =IFERROR(IF(BD5+BE5=0,"",BD5+BE5),"") | BG5: =IFERROR((($CL5/1.15)-(BC5-(BC5*BB$2)))/($CL5/1.15),"") | BH5: =IFERROR((($CM5/1.15)+(BD5+BE5)-(BC5-(BC5*BB$2)))/($CM5/1.15),"") | BI5: {=IFERROR( _xlfn.LET( _xlpm.result, INDEX(_xlfn._xlws.FILTER(ST[6wk avg], (ST[Code]=$C5)*(ST[Customer Name]=BB$3), ""), 1), IF(_xlpm.result=0, "", _xlpm.result) ), "")} | BJ5: =IFERROR(IF(CEILING(BI5 + (BI5 * $BJ$2), 1) = 0, "", CEILING(BI5 + (BI5 * $BJ$2), 1))*$B$3, "") | BK5: =IFERROR((BJ5*BD5),"") | BL5: =IFERROR((BJ5*BE5),"") | BN5: {=IFERROR(_xlfn._xlws.FILTER(#REF!,(#REF!=$C5) * (#REF!=BN$3),"" ),"")} | BO5: {=IFERROR(_xlfn.XLOOKUP($C5,Master_Price_Level_NZ[Code],INDEX(Master_Price_Level_NZ[], , MATCH('Promo Form'!BN$3, Master_Price_Level_NZ[#Headers], 0))),"")} | BP5: =IFERROR(((BO5)*$CN5)*BN$39,"") | BQ5: =IFERROR(((BO5)*$CN5)*BN$38,"") | BR5: =IFERROR(IF(BP5+BQ5=0,"",BP5+BQ5),"") | BS5: =IFERROR((($CL5/1.15)-(BO5-(BO5*BN$2)))/($CL5/1.15),"") | BT5: =IFERROR((($CM5/1.15)+(BP5+BQ5)-(BO5-(BO5*BN$2)))/($CM5/1.15),"") | BU5: {=IFERROR( _xlfn.LET( _xlpm.result, INDEX(_xlfn._xlws.FILTER(ST[6wk avg], (ST[Code]=$C5)*(ST[Customer Name]=BN$3), ""), 1), IF(_xlpm.result=0, "", _xlpm.result) ), "")} | BV5: =IFERROR(IF(CEILING(BU5 + (BU5 * $BV$2), 1) = 0, "", CEILING(BU5 + (BU5 * $BV$2), 1))*$B$3, "") | BW5: =IFERROR((BV5*BP5),"") | BX5: =IFERROR((BV5*BQ5),"") | BZ5: {=IFERROR(_xlfn._xlws.FILTER(#REF!,(#REF!=$C5) * (#REF!=BZ$3),"" ),"")} | CA5: {=IFERROR(_xlfn.XLOOKUP($C5,Master_Price_Level_NZ[Code],INDEX(Master_Price_Level_NZ[], , MATCH('Promo Form'!BZ$3, Master_Price_Level_NZ[#Headers], 0))),"")} | CB5: =IFERROR(((CA5)*$CN5)*BZ$39,"") | CC5: =IFERROR(((CA5)*$CN5)*BZ$38,"") | CD5: =IFERROR(IF(CB5+CC5=0,"",CB5+CC5),"") | CE5: =IFERROR((($CL5/1.15)-(CA5-(CA5*BZ$2)))/($CL5/1.15),"") | CF5: =IFERROR((($CM5/1.1)+(CB5+CC5)-(CA5-(CA5*BZ$2)))/($CM5/1.1),"") | CG5: {=IFERROR( _xlfn.LET( _xlpm.result, INDEX(_xlfn._xlws.FILTER(ST[6wk avg], (ST[Code]=$C5)*(ST[Customer Name]=BZ$3), ""), 1), IF(_xlpm.result=0, "", _xlpm.result) ), "")} | CH5: =IFERROR(IF(CEILING(CG5 + (CG5 * $CH$2), 1) = 0, "", CEILING(CG5 + (CG5 * $CH$2), 1))*$B$3, "") | CI5: =IFERROR((CH5*CB5),"") | CJ5: =IFERROR((CH5*CC5),"") | CL5: =IFERROR(_xlfn.XLOOKUP(C5,Master_Price_Level_NZ[Code],Master_Price_Level_NZ[Base (RRP Inc)]),"") -> 39.99 | CM5: =IFERROR(CL5-(CL5*CN5),"") -> 31.992 | CN5: 0.2 | CO5: =IFERROR((CL5-CM5),"") -> 7.998
A6: =IF(C6="","",A5) | B6: =IF(C6="","",B5) | D6: =IF(C6="", "",_xlfn.XLOOKUP(C6,'Master Price Level NZ'!B:B,'Master Price Level NZ'!C:C)) | G6: {=IFERROR(_xlfn.XLOOKUP($C6,Master_Price_Level_NZ[Code],INDEX(Master_Price_Level_NZ[], , MATCH('Promo Form'!F$3, Master_Price_Level_NZ[#Headers], 0))),"")} | H6: =IFERROR(((G6)*$CN6)*F$39,"") | I6: =IFERROR(((G6)*$CN6)*F$38,"") | J6: =IFERROR(IF(H6+I6=0,"",H6+I6),"") | K6: =IFERROR((($CL6/1.15)-(G6-(G6*F$2)))/($CL6/1.15),"") | L6: =IFERROR((($CM6/1.15)+(H6+I6)-(G6-(G6*F$2)))/($CM6/1.15),"") | M6: {=IFERROR( _xlfn.LET( _xlpm.result, INDEX(_xlfn._xlws.FILTER(ST[6wk avg], (ST[Code]=$C6)*(ST[Customer Name]=F$3), ""), 1), IF(_xlpm.result=0, "", _xlpm.result) ), "")} | N6: =IFERROR(IF(CEILING(M6 + (M6 * $N$2), 1) = 0, "", CEILING(M6 + (M6 * $N$2), 1))*$B$3, "") | O6: =IFERROR((N6*H6),"") | P6: =IFERROR((N6*I6),"") | R6: {=IFERROR(_xlfn._xlws.FILTER(#REF!,(#REF!=$C6) * (#REF!=R$3),"" ),"")} | S6: {=IFERROR(_xlfn.XLOOKUP($C6,Master_Price_Level_NZ[Code],INDEX(Master_Price_Level_NZ[], , MATCH('Promo Form'!R$3, Master_Price_Level_NZ[#Headers], 0))),"")} | T6: =IFERROR(((S6)*$CN6)*R$39,"") | U6: =IFERROR(((S6)*$CN6)*R$38,"") | V6: =IFERROR(IF(T6+U6=0,"",T6+U6),"") | W6: =IFERROR((($CL6/1.15)-(S6-(S6*R$2)))/($CL6/1.15),"") | X6: =IFERROR((($CM6/1.15)+(T6+U6)-(S6-(S6*R$2)))/($CM6/1.15),"") | Y6: {=IFERROR( _xlfn.LET( _xlpm.result, INDEX(_xlfn._xlws.FILTER(ST[6wk avg], (ST[Code]=$C6)*(ST[Customer Name]=R$3), ""), 1), IF(_xlpm.result=0, "", _xlpm.result) ), "")} | Z6: =IFERROR(IF(CEILING(Y6 + (Y6 * $Z$2), 1) = 0, "", CEILING(Y6 + (Y6 * $Z$2), 1))*$B$3, "") | AA6: =IFERROR((Z6*T6),"") | AB6: =IFERROR((Z6*U6),"") | AD6: {=IFERROR(_xlfn._xlws.FILTER(#REF!,(#REF!=$C6) * (#REF!=AD$3),"" ),"")} | AE6: {=IFERROR(_xlfn.XLOOKUP($C6,Master_Price_Level_NZ[Code],INDEX(Master_Price_Level_NZ[], , MATCH('Promo Form'!AD$3, Master_Price_Level_NZ[#Headers], 0))),"")} | AF6: =IFERROR(((AE6)*$CN6)*AD$39,"") | AG6: =IFERROR(((AE6)*$CN6)*AD$38,"") | AH6: =IFERROR(IF(AF6+AG6=0,"",AF6+AG6),"") | AI6: =IFERROR((($CL6/1.15)-(AE6-(AE6*AD$2)))/($CL6/1.15),"") | AJ6: =IFERROR((($CM6/1.15)+(AF6+AG6)-(AE6-(AE6*AD$2)))/($CM6/1.15),"") | AK6: {=IFERROR( _xlfn.LET( _xlpm.result, INDEX(_xlfn._xlws.FILTER(ST[6wk avg], (ST[Code]=$C6)*(ST[Customer Name]=AD$3), ""), 1), IF(_xlpm.result=0, "", _xlpm.result) ), "")} | AL6: =IFERROR(IF(CEILING(AK6 + (AK6 * $AL$2), 1) = 0, "", CEILING(AK6 + (AK6 * $AL$2), 1))*$B$3, "") | AM6: =IFERROR((AL6*AF6),"") | AN6: =IFERROR((AL6*AG6),"") | AP6: {=IFERROR(_xlfn._xlws.FILTER(#REF!,(#REF!=$C6) * (#REF!=AP$3),"" ),"")} | AQ6: {=IFERROR(_xlfn.XLOOKUP($C6,Master_Price_Level_NZ[Code],INDEX(Master_Price_Level_NZ[], , MATCH('Promo Form'!AP$3, Master_Price_Level_NZ[#Headers], 0))),"")} | AR6: =IFERROR(((AQ6)*$CN6)*AP$39,"") | AS6: =IFERROR(((AQ6)*$CN6)*AP$38,"") | AT6: =IFERROR(IF(AR6+AS6=0,"",AR6+AS6),"") | AU6: =IFERROR((($CL6/1.15)-(AQ6-(AQ6*AP$2)))/($CL6/1.15),"") | AV6: =IFERROR((($CM6/1.15)+(AR6+AS6)-(AQ6-(AQ6*AP$2)))/($CM6/1.15),"") | AW6: {=IFERROR( _xlfn.LET( _xlpm.result, INDEX(_xlfn._xlws.FILTER(ST[6wk avg], (ST[Code]=$C6)*(ST[Customer Name]=AP$3), ""), 1), IF(_xlpm.result=0, "", _xlpm.result) ), "")} | AX6: =IFERROR(IF(CEILING(AW6 + (AW6 * $AX$2), 1) = 0, "", CEILING(AW6 + (AW6 * $AX$2), 1))*$B$3, "") | AY6: =IFERROR((AX6*AR6),"") | AZ6: =IFERROR((AX6*AS6),"") | BB6: {=IFERROR(_xlfn._xlws.FILTER(#REF!,(#REF!=$C6) * (#REF!=BB$3),"" ),"")} | BC6: {=IFERROR(_xlfn.XLOOKUP($C6,Master_Price_Level_NZ[Code],INDEX(Master_Price_Level_NZ[], , MATCH('Promo Form'!BB$3, Master_Price_Level_NZ[#Headers], 0))),"")} | BD6: =IFERROR(((BC6)*$CN6)*BB$39,"") | BE6: =IFERROR(((BC6)*$CN6)*BB$38,"") | BF6: =IFERROR(IF(BD6+BE6=0,"",BD6+BE6),"") | BG6: =IFERROR((($CL6/1.15)-(BC6-(BC6*BB$2)))/($CL6/1.15),"") | BH6: =IFERROR((($CM6/1.15)+(BD6+BE6)-(BC6-(BC6*BB$2)))/($CM6/1.15),"") | BI6: {=IFERROR( _xlfn.LET( _xlpm.result, INDEX(_xlfn._xlws.FILTER(ST[6wk avg], (ST[Code]=$C6)*(ST[Customer Name]=BB$3), ""), 1), IF(_xlpm.result=0, "", _xlpm.result) ), "")} | BJ6: =IFERROR(IF(CEILING(BI6 + (BI6 * $BJ$2), 1) = 0, "", CEILING(BI6 + (BI6 * $BJ$2), 1))*$B$3, "") | BK6: =IFERROR((BJ6*BD6),"") | BL6: =IFERROR((BJ6*BE6),"") | BN6: {=IFERROR(_xlfn._xlws.FILTER(#REF!,(#REF!=$C6) * (#REF!=BN$3),"" ),"")} | BO6: {=IFERROR(_xlfn.XLOOKUP($C6,Master_Price_Level_NZ[Code],INDEX(Master_Price_Level_NZ[], , MATCH('Promo Form'!BN$3, Master_Price_Level_NZ[#Headers], 0))),"")} | BP6: =IFERROR(((BO6)*$CN6)*BN$39,"") | BQ6: =IFERROR(((BO6)*$CN6)*BN$38,"") | BR6: =IFERROR(IF(BP6+BQ6=0,"",BP6+BQ6),"") | BS6: =IFERROR((($CL6/1.15)-(BO6-(BO6*BN$2)))/($CL6/1.15),"") | BT6: =IFERROR((($CM6/1.15)+(BP6+BQ6)-(BO6-(BO6*BN$2)))/($CM6/1.15),"") | BU6: {=IFERROR( _xlfn.LET( _xlpm.result, INDEX(_xlfn._xlws.FILTER(ST[6wk avg], (ST[Code]=$C6)*(ST[Customer Name]=BN$3), ""), 1), IF(_xlpm.result=0, "", _xlpm.result) ), "")} | BV6: =IFERROR(IF(CEILING(BU6 + (BU6 * $BV$2), 1) = 0, "", CEILING(BU6 + (BU6 * $BV$2), 1))*$B$3, "") | BW6: =IFERROR((BV6*BP6),"") | BX6: =IFERROR((BV6*BQ6),"") | BZ6: {=IFERROR(_xlfn._xlws.FILTER(#REF!,(#REF!=$C6) * (#REF!=BZ$3),"" ),"")} | CA6: {=IFERROR(_xlfn.XLOOKUP($C6,Master_Price_Level_NZ[Code],INDEX(Master_Price_Level_NZ[], , MATCH('Promo Form'!BZ$3, Master_Price_Level_NZ[#Headers], 0))),"")} | CB6: =IFERROR(((CA6)*$CN6)*BZ$39,"") | CC6: =IFERROR(((CA6)*$CN6)*BZ$38,"") | CD6: =IFERROR(IF(CB6+CC6=0,"",CB6+CC6),"") | CE6: =IFERROR((($CL6/1.15)-(CA6-(CA6*BZ$2)))/($CL6/1.15),"") | CF6: =IFERROR((($CM6/1.1)+(CB6+CC6)-(CA6-(CA6*BZ$2)))/($CM6/1.1),"") | CG6: {=IFERROR( _xlfn.LET( _xlpm.result, INDEX(_xlfn._xlws.FILTER(ST[6wk avg], (ST[Code]=$C6)*(ST[Customer Name]=BZ$3), ""), 1), IF(_xlpm.result=0, "", _xlpm.result) ), "")} | CH6: =IFERROR(IF(CEILING(CG6 + (CG6 * $CH$2), 1) = 0, "", CEILING(CG6 + (CG6 * $CH$2), 1))*$B$3, "") | CI6: =IFERROR((CH6*CB6),"") | CJ6: =IFERROR((CH6*CC6),"") | CL6: =IFERROR(_xlfn.XLOOKUP(C6,Master_Price_Level_NZ[Code],Master_Price_Level_NZ[Base (RRP Inc)]),"") | CM6: =IFERROR(CL6-(CL6*CN6),"") | CN6: =IF(C6="", "",CN5) | CO6: =IFERROR((CL6-CM6),"")
A7: =IF(C7="","",A6) | B7: =IF(C7="","",B6) | D7: =IF(C7="", "",_xlfn.XLOOKUP(C7,'Master Price Level NZ'!B:B,'Master Price Level NZ'!C:C)) | G7: {=IFERROR(_xlfn.XLOOKUP($C7,Master_Price_Level_NZ[Code],INDEX(Master_Price_Level_NZ[], , MATCH('Promo Form'!F$3, Master_Price_Level_NZ[#Headers], 0))),"")} | H7: =IFERROR(((G7*(1-F$2))*$CN7)*F$39,"") | I7: =IFERROR(((G7*(1-F$2))*$CN7)*F$38,"") | J7: =IFERROR(IF(H7+I7=0,"",H7+I7),"") | K7: =IFERROR((($CL7/1.15)-(G7-(G7*F$2)))/($CL7/1.15),"") | L7: =IFERROR((($CM7/1.15)+(H7+I7)-(G7-(G7*F$2)))/($CM7/1.15),"") | M7: {=IF($C7="","",IFERROR(_xlfn._xlws.FILTER(ST[6wk avg],(ST[Code]=$C7)*(ST[Customer Name]=F$3),""),""))} | N7: =IFERROR(IF(CEILING(M7 + (M7 * $N$2), 1) = 0, "", CEILING(M7 + (M7 * $N$2), 1))*$B$3, "") | O7: =IFERROR((N7*H7),"") | P7: =IFERROR((N7*I7),"") | R7: {=IFERROR(_xlfn._xlws.FILTER(#REF!,(#REF!=$C7) * (#REF!=R$3),"" ),"")} | S7: {=IFERROR(_xlfn.XLOOKUP($C7,Master_Price_Level_NZ[Code],INDEX(Master_Price_Level_NZ[], , MATCH('Promo Form'!R$3, Master_Price_Level_NZ[#Headers], 0))),"")} | T7: =IFERROR(((S7*(1-R$2))*$CN7)*R$39,"") | U7: =IFERROR(((S7*(1-R$2))*$CN7)*R$38,"") | V7: =IFERROR(IF(T7+U7=0,"",T7+U7),"") | W7: =IFERROR((($CL7/1.15)-(S7-(S7*R$2)))/($CL7/1.15),"") | X7: =IFERROR((($CM7/1.15)+(T7+U7)-(S7-(S7*R$2)))/($CM7/1.15),"") | Y7: {=IFERROR( _xlfn.LET( _xlpm.result, INDEX(_xlfn._xlws.FILTER(ST[6wk avg], (ST[Code]=$C7)*(ST[Customer Name]=R$3), ""), 1), IF(_xlpm.result=0, "", _xlpm.result) ), "")} | Z7: =IFERROR(IF(CEILING(Y7 + (Y7 * $N$2), 1) = 0, "", CEILING(Y7 + (Y7 * $N$2), 1))*$B$3, "") | AA7: =IFERROR((Z7*T7),"") | AB7: =IFERROR((Z7*U7),"") | AD7: {=IFERROR(_xlfn._xlws.FILTER(#REF!,(#REF!=$C7) * (#REF!=AD$3),"" ),"")} | AE7: {=IFERROR(_xlfn.XLOOKUP($C7,Master_Price_Level_NZ[Code],INDEX(Master_Price_Level_NZ[], , MATCH('Promo Form'!AD$3, Master_Price_Level_NZ[#Headers], 0))),"")} | AF7: =IFERROR(((AE7*(1-AD$2))*$CN7)*AD$39,"") | AG7: =IFERROR(((AE7*(1-AD$2))*$CN7)*AD$38,"") | AH7: =IFERROR(IF(AF7+AG7=0,"",AF7+AG7),"") | AI7: =IFERROR((($CL7/1.15)-(AE7-(AE7*AD$2)))/($CL7/1.15),"") | AJ7: =IFERROR((($CM7/1.15)+(AF7+AG7)-(AE7-(AE7*AD$2)))/($CM7/1.15),"") | AK7: {=IFERROR( _xlfn.LET( _xlpm.result, INDEX(_xlfn._xlws.FILTER(ST[6wk avg], (ST[Code]=$C7)*(ST[Customer Name]=AD$3), ""), 1), IF(_xlpm.result=0, "", _xlpm.result) ), "")} | AL7: =IFERROR(IF(CEILING(AK7 + (AK7 * $N$2), 1) = 0, "", CEILING(AK7 + (AK7 * $N$2), 1))*$B$3, "") | AM7: =IFERROR((AL7*AF7),"") | AN7: =IFERROR((AL7*AG7),"") | AP7: {=IFERROR(_xlfn._xlws.FILTER(#REF!,(#REF!=$C7) * (#REF!=AP$3),"" ),"")} | AQ7: {=IFERROR(_xlfn.XLOOKUP($C7,Master_Price_Level_NZ[Code],INDEX(Master_Price_Level_NZ[], , MATCH('Promo Form'!AP$3, Master_Price_Level_NZ[#Headers], 0))),"")} | AR7: =IFERROR(((AQ7*(1-AP$2))*$CN7)*AP$39,"") | AS7: =IFERROR(((AQ7*(1-AP$2))*$CN7)*AP$38,"") | AT7: =IFERROR(IF(AR7+AS7=0,"",AR7+AS7),"") | AU7: =IFERROR((($CL7/1.15)-(AQ7-(AQ7*AP$2)))/($CL7/1.15),"") | AV7: =IFERROR((($CM7/1.15)+(AR7+AS7)-(AQ7-(AQ7*AP$2)))/($CM7/1.15),"") | AW7: {=IFERROR( _xlfn.LET( _xlpm.result, INDEX(_xlfn._xlws.FILTER(ST[6wk avg], (ST[Code]=$C7)*(ST[Customer Name]=AP$3), ""), 1), IF(_xlpm.result=0, "", _xlpm.result) ), "")} | AX7: =IFERROR(IF(CEILING(AW7 + (AW7 * $N$2), 1) = 0, "", CEILING(AW7 + (AW7 * $N$2), 1))*$B$3, "") | AY7: =IFERROR((AX7*AR7),"") | AZ7: =IFERROR((AX7*AS7),"") | BB7: {=IFERROR(_xlfn._xlws.FILTER(#REF!,(#REF!=$C7) * (#REF!=BB$3),"" ),"")} | BC7: {=IFERROR(_xlfn.XLOOKUP($C7,Master_Price_Level_NZ[Code],INDEX(Master_Price_Level_NZ[], , MATCH('Promo Form'!BB$3, Master_Price_Level_NZ[#Headers], 0))),"")} | BD7: =IFERROR(((BC7*(1-BB$2))*$CN7)*BB$39,"") | BE7: =IFERROR(((BC7*(1-BB$2))*$CN7)*BB$38,"") | BF7: =IFERROR(IF(BD7+BE7=0,"",BD7+BE7),"") | BG7: =IFERROR((($CL7/1.15)-(BC7-(BC7*BB$2)))/($CL7/1.15),"") | BH7: =IFERROR((($CM7/1.15)+(BD7+BE7)-(BC7-(BC7*BB$2)))/($CM7/1.15),"") | BI7: {=IFERROR( _xlfn.LET( _xlpm.result, INDEX(_xlfn._xlws.FILTER(ST[6wk avg], (ST[Code]=$C7)*(ST[Customer Name]=BB$3), ""), 1), IF(_xlpm.result=0, "", _xlpm.result) ), "")} | BJ7: =IFERROR(IF(CEILING(BI7 + (BI7 * $N$2), 1) = 0, "", CEILING(BI7 + (BI7 * $N$2), 1))*$B$3, "") | BK7: =IFERROR((BJ7*BD7),"") | BL7: =IFERROR((BJ7*BE7),"") | BN7: {=IFERROR(_xlfn._xlws.FILTER(#REF!,(#REF!=$C7) * (#REF!=BN$3),"" ),"")} | BO7: {=IFERROR(_xlfn.XLOOKUP($C7,Master_Price_Level_NZ[Code],INDEX(Master_Price_Level_NZ[], , MATCH('Promo Form'!BN$3, Master_Price_Level_NZ[#Headers], 0))),"")} | BP7: =IFERROR(((BO7*(1-BN$2))*$CN7)*BN$39,"") | BQ7: =IFERROR(((BO7*(1-BN$2))*$CN7)*BN$38,"") | BR7: =IFERROR(IF(BP7+BQ7=0,"",BP7+BQ7),"") | BS7: =IFERROR((($CL7/1.15)-(BO7-(BO7*BN$2)))/($CL7/1.15),"") | BT7: =IFERROR((($CM7/1.15)+(BP7+BQ7)-(BO7-(BO7*BN$2)))/($CM7/1.15),"") | BU7: {=IFERROR( _xlfn.LET( _xlpm.result, INDEX(_xlfn._xlws.FILTER(ST[6wk avg], (ST[Code]=$C7)*(ST[Customer Name]=BN$3), ""), 1), IF(_xlpm.result=0, "", _xlpm.result) ), "")} | BV7: =IFERROR(IF(CEILING(BU7 + (BU7 * $N$2), 1) = 0, "", CEILING(BU7 + (BU7 * $N$2), 1))*$B$3, "") | BW7: =IFERROR((BV7*BP7),"") | BX7: =IFERROR((BV7*BQ7),"") | BZ7: {=IFERROR(_xlfn._xlws.FILTER(#REF!,(#REF!=$C7) * (#REF!=BZ$3),"" ),"")} | CA7: {=IFERROR(_xlfn.XLOOKUP($C7,Master_Price_Level_NZ[Code],INDEX(Master_Price_Level_NZ[], , MATCH('Promo Form'!BZ$3, Master_Price_Level_NZ[#Headers], 0))),"")} | CB7: =IFERROR(((CA7*(1-BZ$2))*$CN7)*BZ$39,"") | CC7: =IFERROR(((CA7*(1-BZ$2))*$CN7)*BZ$38,"") | CD7: =IFERROR(IF(CB7+CC7=0,"",CB7+CC7),"") | CE7: =IFERROR((($CL7/1.15)-(CA7-(CA7*BZ$2)))/($CL7/1.15),"") | CF7: =IFERROR((($CM7/1.15)+(CB7+CC7)-(CA7-(CA7*BZ$2)))/($CM7/1.15),"") | CG7: {=IFERROR( _xlfn.LET( _xlpm.result, INDEX(_xlfn._xlws.FILTER(ST[6wk avg], (ST[Code]=$C7)*(ST[Customer Name]=BZ$3), ""), 1), IF(_xlpm.result=0, "", _xlpm.result) ), "")} | CH7: =IFERROR(IF(CEILING(CG7 + (CG7 * $N$2), 1) = 0, "", CEILING(CG7 + (CG7 * $N$2), 1))*$B$3, "") | CI7: =IFERROR((CH7*CB7),"") | CJ7: =IFERROR((CH7*CC7),"") | CL7: =IFERROR(_xlfn.XLOOKUP(C7,Master_Price_Level_NZ[Code],Master_Price_Level_NZ[Base (RRP Inc)]),"") | CM7: =IFERROR(CL7-(CL7*CN7),"") | CN7: =IF(C7="", "",CN6) | CO7: =IFERROR((CL7-CM7),"")
A8: =IF(C8="","",A7) | B8: =IF(C8="","",B7) | D8: =IF(C8="", "",_xlfn.XLOOKUP(C8,'Master Price Level NZ'!B:B,'Master Price Level NZ'!C:C)) | G8: {=IFERROR(_xlfn.XLOOKUP($C8,Master_Price_Level_NZ[Code],INDEX(Master_Price_Level_NZ[], , MATCH('Promo Form'!F$3, Master_Price_Level_NZ[#Headers], 0))),"")} | H8: =IFERROR(((G8*(1-F$2))*$CN8)*F$39,"") | I8: =IFERROR(((G8*(1-F$2))*$CN8)*F$38,"") | J8: =IFERROR(IF(H8+I8=0,"",H8+I8),"") | K8: =IFERROR((($CL8/1.15)-(G8-(G8*F$2)))/($CL8/1.15),"") | L8: =IFERROR((($CM8/1.15)+(H8+I8)-(G8-(G8*F$2)))/($CM8/1.15),"") | M8: {=IF($C8="","",IFERROR(_xlfn._xlws.FILTER(ST[6wk avg],(ST[Code]=$C8)*(ST[Customer Name]=F$3),""),""))} | N8: =IFERROR(IF(CEILING(M8 + (M8 * $N$2), 1) = 0, "", CEILING(M8 + (M8 * $N$2), 1))*$B$3, "") | O8: =IFERROR((N8*H8),"") | P8: =IFERROR((N8*I8),"") | R8: {=IFERROR(_xlfn._xlws.FILTER(#REF!,(#REF!=$C8) * (#REF!=R$3),"" ),"")} | S8: {=IFERROR(_xlfn.XLOOKUP($C8,Master_Price_Level_NZ[Code],INDEX(Master_Price_Level_NZ[], , MATCH('Promo Form'!R$3, Master_Price_Level_NZ[#Headers], 0))),"")} | T8: =IFERROR(((S8*(1-R$2))*$CN8)*R$39,"") | U8: =IFERROR(((S8*(1-R$2))*$CN8)*R$38,"") | V8: =IFERROR(IF(T8+U8=0,"",T8+U8),"") | W8: =IFERROR((($CL8/1.15)-(S8-(S8*R$2)))/($CL8/1.15),"") | X8: =IFERROR((($CM8/1.15)+(T8+U8)-(S8-(S8*R$2)))/($CM8/1.15),"") | Y8: {=IFERROR( _xlfn.LET( _xlpm.result, INDEX(_xlfn._xlws.FILTER(ST[6wk avg], (ST[Code]=$C8)*(ST[Customer Name]=R$3), ""), 1), IF(_xlpm.result=0, "", _xlpm.result) ), "")} | Z8: =IFERROR(IF(CEILING(Y8 + (Y8 * $N$2), 1) = 0, "", CEILING(Y8 + (Y8 * $N$2), 1))*$B$3, "") | AA8: =IFERROR((Z8*T8),"") | AB8: =IFERROR((Z8*U8),"") | AD8: {=IFERROR(_xlfn._xlws.FILTER(#REF!,(#REF!=$C8) * (#REF!=AD$3),"" ),"")} | AE8: {=IFERROR(_xlfn.XLOOKUP($C8,Master_Price_Level_NZ[Code],INDEX(Master_Price_Level_NZ[], , MATCH('Promo Form'!AD$3, Master_Price_Level_NZ[#Headers], 0))),"")} | AF8: =IFERROR(((AE8*(1-AD$2))*$CN8)*AD$39,"") | AG8: =IFERROR(((AE8*(1-AD$2))*$CN8)*AD$38,"") | AH8: =IFERROR(IF(AF8+AG8=0,"",AF8+AG8),"") | AI8: =IFERROR((($CL8/1.15)-(AE8-(AE8*AD$2)))/($CL8/1.15),"") | AJ8: =IFERROR((($CM8/1.15)+(AF8+AG8)-(AE8-(AE8*AD$2)))/($CM8/1.15),"") | AK8: {=IFERROR( _xlfn.LET( _xlpm.result, INDEX(_xlfn._xlws.FILTER(ST[6wk avg], (ST[Code]=$C8)*(ST[Customer Name]=AD$3), ""), 1), IF(_xlpm.result=0, "", _xlpm.result) ), "")} | AL8: =IFERROR(IF(CEILING(AK8 + (AK8 * $N$2), 1) = 0, "", CEILING(AK8 + (AK8 * $N$2), 1))*$B$3, "") | AM8: =IFERROR((AL8*AF8),"") | AN8: =IFERROR((AL8*AG8),"") | AP8: {=IFERROR(_xlfn._xlws.FILTER(#REF!,(#REF!=$C8) * (#REF!=AP$3),"" ),"")} | AQ8: {=IFERROR(_xlfn.XLOOKUP($C8,Master_Price_Level_NZ[Code],INDEX(Master_Price_Level_NZ[], , MATCH('Promo Form'!AP$3, Master_Price_Level_NZ[#Headers], 0))),"")} | AR8: =IFERROR(((AQ8*(1-AP$2))*$CN8)*AP$39,"") | AS8: =IFERROR(((AQ8*(1-AP$2))*$CN8)*AP$38,"") | AT8: =IFERROR(IF(AR8+AS8=0,"",AR8+AS8),"") | AU8: =IFERROR((($CL8/1.15)-(AQ8-(AQ8*AP$2)))/($CL8/1.15),"") | AV8: =IFERROR((($CM8/1.15)+(AR8+AS8)-(AQ8-(AQ8*AP$2)))/($CM8/1.15),"") | AW8: {=IFERROR( _xlfn.LET( _xlpm.result, INDEX(_xlfn._xlws.FILTER(ST[6wk avg], (ST[Code]=$C8)*(ST[Customer Name]=AP$3), ""), 1), IF(_xlpm.result=0, "", _xlpm.result) ), "")} | AX8: =IFERROR(IF(CEILING(AW8 + (AW8 * $N$2), 1) = 0, "", CEILING(AW8 + (AW8 * $N$2), 1))*$B$3, "") | AY8: =IFERROR((AX8*AR8),"") | AZ8: =IFERROR((AX8*AS8),"") | BB8: {=IFERROR(_xlfn._xlws.FILTER(#REF!,(#REF!=$C8) * (#REF!=BB$3),"" ),"")} | BC8: {=IFERROR(_xlfn.XLOOKUP($C8,Master_Price_Level_NZ[Code],INDEX(Master_Price_Level_NZ[], , MATCH('Promo Form'!BB$3, Master_Price_Level_NZ[#Headers], 0))),"")} | BD8: =IFERROR(((BC8*(1-BB$2))*$CN8)*BB$39,"") | BE8: =IFERROR(((BC8*(1-BB$2))*$CN8)*BB$38,"") | BF8: =IFERROR(IF(BD8+BE8=0,"",BD8+BE8),"") | BG8: =IFERROR((($CL8/1.15)-(BC8-(BC8*BB$2)))/($CL8/1.15),"") | BH8: =IFERROR((($CM8/1.15)+(BD8+BE8)-(BC8-(BC8*BB$2)))/($CM8/1.15),"") | BI8: {=IFERROR( _xlfn.LET( _xlpm.result, INDEX(_xlfn._xlws.FILTER(ST[6wk avg], (ST[Code]=$C8)*(ST[Customer Name]=BB$3), ""), 1), IF(_xlpm.result=0, "", _xlpm.result) ), "")} | BJ8: =IFERROR(IF(CEILING(BI8 + (BI8 * $N$2), 1) = 0, "", CEILING(BI8 + (BI8 * $N$2), 1))*$B$3, "") | BK8: =IFERROR((BJ8*BD8),"") | BL8: =IFERROR((BJ8*BE8),"") | BN8: {=IFERROR(_xlfn._xlws.FILTER(#REF!,(#REF!=$C8) * (#REF!=BN$3),"" ),"")} | BO8: {=IFERROR(_xlfn.XLOOKUP($C8,Master_Price_Level_NZ[Code],INDEX(Master_Price_Level_NZ[], , MATCH('Promo Form'!BN$3, Master_Price_Level_NZ[#Headers], 0))),"")} | BP8: =IFERROR(((BO8*(1-BN$2))*$CN8)*BN$39,"") | BQ8: =IFERROR(((BO8*(1-BN$2))*$CN8)*BN$38,"") | BR8: =IFERROR(IF(BP8+BQ8=0,"",BP8+BQ8),"") | BS8: =IFERROR((($CL8/1.15)-(BO8-(BO8*BN$2)))/($CL8/1.15),"") | BT8: =IFERROR((($CM8/1.15)+(BP8+BQ8)-(BO8-(BO8*BN$2)))/($CM8/1.15),"") | BU8: {=IFERROR( _xlfn.LET( _xlpm.result, INDEX(_xlfn._xlws.FILTER(ST[6wk avg], (ST[Code]=$C8)*(ST[Customer Name]=BN$3), ""), 1), IF(_xlpm.result=0, "", _xlpm.result) ), "")} | BV8: =IFERROR(IF(CEILING(BU8 + (BU8 * $N$2), 1) = 0, "", CEILING(BU8 + (BU8 * $N$2), 1))*$B$3, "") | BW8: =IFERROR((BV8*BP8),"") | BX8: =IFERROR((BV8*BQ8),"") | BZ8: {=IFERROR(_xlfn._xlws.FILTER(#REF!,(#REF!=$C8) * (#REF!=BZ$3),"" ),"")} | CA8: {=IFERROR(_xlfn.XLOOKUP($C8,Master_Price_Level_NZ[Code],INDEX(Master_Price_Level_NZ[], , MATCH('Promo Form'!BZ$3, Master_Price_Level_NZ[#Headers], 0))),"")} | CB8: =IFERROR(((CA8*(1-BZ$2))*$CN8)*BZ$39,"") | CC8: =IFERROR(((CA8*(1-BZ$2))*$CN8)*BZ$38,"") | CD8: =IFERROR(IF(CB8+CC8=0,"",CB8+CC8),"") | CE8: =IFERROR((($CL8/1.15)-(CA8-(CA8*BZ$2)))/($CL8/1.15),"") | CF8: =IFERROR((($CM8/1.15)+(CB8+CC8)-(CA8-(CA8*BZ$2)))/($CM8/1.15),"") | CG8: {=IFERROR( _xlfn.LET( _xlpm.result, INDEX(_xlfn._xlws.FILTER(ST[6wk avg], (ST[Code]=$C8)*(ST[Customer Name]=BZ$3), ""), 1), IF(_xlpm.result=0, "", _xlpm.result) ), "")} | CH8: =IFERROR(IF(CEILING(CG8 + (CG8 * $N$2), 1) = 0, "", CEILING(CG8 + (CG8 * $N$2), 1))*$B$3, "") | CI8: =IFERROR((CH8*CB8),"") | CJ8: =IFERROR((CH8*CC8),"") | CL8: =IFERROR(_xlfn.XLOOKUP(C8,Master_Price_Level_NZ[Code],Master_Price_Level_NZ[Base (RRP Inc)]),"") | CM8: =IFERROR(CL8-(CL8*CN8),"") | CN8: =IF(C8="", "",CN7) | CO8: =IFERROR((CL8-CM8),"")
A9: =IF(C9="","",A8) | B9: =IF(C9="","",B8) | D9: =IF(C9="", "",_xlfn.XLOOKUP(C9,'Master Price Level NZ'!B:B,'Master Price Level NZ'!C:C)) | G9: {=IFERROR(_xlfn.XLOOKUP($C9,Master_Price_Level_NZ[Code],INDEX(Master_Price_Level_NZ[], , MATCH('Promo Form'!F$3, Master_Price_Level_NZ[#Headers], 0))),"")} | H9: =IFERROR(((G9*(1-F$2))*$CN9)*F$39,"") | I9: =IFERROR(((G9*(1-F$2))*$CN9)*F$38,"") | J9: =IFERROR(IF(H9+I9=0,"",H9+I9),"") | K9: =IFERROR((($CL9/1.15)-(G9-(G9*F$2)))/($CL9/1.15),"") | L9: =IFERROR((($CM9/1.15)+(H9+I9)-(G9-(G9*F$2)))/($CM9/1.15),"") | M9: {=IF($C9="","",IFERROR(_xlfn._xlws.FILTER(ST[6wk avg],(ST[Code]=$C9)*(ST[Customer Name]=F$3),""),""))} | N9: =IFERROR(IF(CEILING(M9 + (M9 * $N$2), 1) = 0, "", CEILING(M9 + (M9 * $N$2), 1))*$B$3, "") | O9: =IFERROR((N9*H9),"") | P9: =IFERROR((N9*I9),"") | R9: {=IFERROR(_xlfn._xlws.FILTER(#REF!,(#REF!=$C9) * (#REF!=R$3),"" ),"")} | S9: {=IFERROR(_xlfn.XLOOKUP($C9,Master_Price_Level_NZ[Code],INDEX(Master_Price_Level_NZ[], , MATCH('Promo Form'!R$3, Master_Price_Level_NZ[#Headers], 0))),"")} | T9: =IFERROR(((S9*(1-R$2))*$CN9)*R$39,"") | U9: =IFERROR(((S9*(1-R$2))*$CN9)*R$38,"") | V9: =IFERROR(IF(T9+U9=0,"",T9+U9),"") | W9: =IFERROR((($CL9/1.15)-(S9-(S9*R$2)))/($CL9/1.15),"") | X9: =IFERROR((($CM9/1.15)+(T9+U9)-(S9-(S9*R$2)))/($CM9/1.15),"") | Y9: {=IFERROR( _xlfn.LET( _xlpm.result, INDEX(_xlfn._xlws.FILTER(ST[6wk avg], (ST[Code]=$C9)*(ST[Customer Name]=R$3), ""), 1), IF(_xlpm.result=0, "", _xlpm.result) ), "")} | Z9: =IFERROR(IF(CEILING(Y9 + (Y9 * $N$2), 1) = 0, "", CEILING(Y9 + (Y9 * $N$2), 1))*$B$3, "") | AA9: =IFERROR((Z9*T9),"") | AB9: =IFERROR((Z9*U9),"") | AD9: {=IFERROR(_xlfn._xlws.FILTER(#REF!,(#REF!=$C9) * (#REF!=AD$3),"" ),"")} | AE9: {=IFERROR(_xlfn.XLOOKUP($C9,Master_Price_Level_NZ[Code],INDEX(Master_Price_Level_NZ[], , MATCH('Promo Form'!AD$3, Master_Price_Level_NZ[#Headers], 0))),"")} | AF9: =IFERROR(((AE9*(1-AD$2))*$CN9)*AD$39,"") | AG9: =IFERROR(((AE9*(1-AD$2))*$CN9)*AD$38,"") | AH9: =IFERROR(IF(AF9+AG9=0,"",AF9+AG9),"") | AI9: =IFERROR((($CL9/1.15)-(AE9-(AE9*AD$2)))/($CL9/1.15),"") | AJ9: =IFERROR((($CM9/1.15)+(AF9+AG9)-(AE9-(AE9*AD$2)))/($CM9/1.15),"") | AK9: {=IFERROR( _xlfn.LET( _xlpm.result, INDEX(_xlfn._xlws.FILTER(ST[6wk avg], (ST[Code]=$C9)*(ST[Customer Name]=AD$3), ""), 1), IF(_xlpm.result=0, "", _xlpm.result) ), "")} | AL9: =IFERROR(IF(CEILING(AK9 + (AK9 * $N$2), 1) = 0, "", CEILING(AK9 + (AK9 * $N$2), 1))*$B$3, "") | AM9: =IFERROR((AL9*AF9),"") | AN9: =IFERROR((AL9*AG9),"") | AP9: {=IFERROR(_xlfn._xlws.FILTER(#REF!,(#REF!=$C9) * (#REF!=AP$3),"" ),"")} | AQ9: {=IFERROR(_xlfn.XLOOKUP($C9,Master_Price_Level_NZ[Code],INDEX(Master_Price_Level_NZ[], , MATCH('Promo Form'!AP$3, Master_Price_Level_NZ[#Headers], 0))),"")} | AR9: =IFERROR(((AQ9*(1-AP$2))*$CN9)*AP$39,"") | AS9: =IFERROR(((AQ9*(1-AP$2))*$CN9)*AP$38,"") | AT9: =IFERROR(IF(AR9+AS9=0,"",AR9+AS9),"") | AU9: =IFERROR((($CL9/1.15)-(AQ9-(AQ9*AP$2)))/($CL9/1.15),"") | AV9: =IFERROR((($CM9/1.15)+(AR9+AS9)-(AQ9-(AQ9*AP$2)))/($CM9/1.15),"") | AW9: {=IFERROR( _xlfn.LET( _xlpm.result, INDEX(_xlfn._xlws.FILTER(ST[6wk avg], (ST[Code]=$C9)*(ST[Customer Name]=AP$3), ""), 1), IF(_xlpm.result=0, "", _xlpm.result) ), "")} | AX9: =IFERROR(IF(CEILING(AW9 + (AW9 * $N$2), 1) = 0, "", CEILING(AW9 + (AW9 * $N$2), 1))*$B$3, "") | AY9: =IFERROR((AX9*AR9),"") | AZ9: =IFERROR((AX9*AS9),"") | BB9: {=IFERROR(_xlfn._xlws.FILTER(#REF!,(#REF!=$C9) * (#REF!=BB$3),"" ),"")} | BC9: {=IFERROR(_xlfn.XLOOKUP($C9,Master_Price_Level_NZ[Code],INDEX(Master_Price_Level_NZ[], , MATCH('Promo Form'!BB$3, Master_Price_Level_NZ[#Headers], 0))),"")} | BD9: =IFERROR(((BC9*(1-BB$2))*$CN9)*BB$39,"") | BE9: =IFERROR(((BC9*(1-BB$2))*$CN9)*BB$38,"") | BF9: =IFERROR(IF(BD9+BE9=0,"",BD9+BE9),"") | BG9: =IFERROR((($CL9/1.15)-(BC9-(BC9*BB$2)))/($CL9/1.15),"") | BH9: =IFERROR((($CM9/1.15)+(BD9+BE9)-(BC9-(BC9*BB$2)))/($CM9/1.15),"") | BI9: {=IFERROR( _xlfn.LET( _xlpm.result, INDEX(_xlfn._xlws.FILTER(ST[6wk avg], (ST[Code]=$C9)*(ST[Customer Name]=BB$3), ""), 1), IF(_xlpm.result=0, "", _xlpm.result) ), "")} | BJ9: =IFERROR(IF(CEILING(BI9 + (BI9 * $N$2), 1) = 0, "", CEILING(BI9 + (BI9 * $N$2), 1))*$B$3, "") | BK9: =IFERROR((BJ9*BD9),"") | BL9: =IFERROR((BJ9*BE9),"") | BN9: {=IFERROR(_xlfn._xlws.FILTER(#REF!,(#REF!=$C9) * (#REF!=BN$3),"" ),"")} | BO9: {=IFERROR(_xlfn.XLOOKUP($C9,Master_Price_Level_NZ[Code],INDEX(Master_Price_Level_NZ[], , MATCH('Promo Form'!BN$3, Master_Price_Level_NZ[#Headers], 0))),"")} | BP9: =IFERROR(((BO9*(1-BN$2))*$CN9)*BN$39,"") | BQ9: =IFERROR(((BO9*(1-BN$2))*$CN9)*BN$38,"") | BR9: =IFERROR(IF(BP9+BQ9=0,"",BP9+BQ9),"") | BS9: =IFERROR((($CL9/1.15)-(BO9-(BO9*BN$2)))/($CL9/1.15),"") | BT9: =IFERROR((($CM9/1.15)+(BP9+BQ9)-(BO9-(BO9*BN$2)))/($CM9/1.15),"") | BU9: {=IFERROR( _xlfn.LET( _xlpm.result, INDEX(_xlfn._xlws.FILTER(ST[6wk avg], (ST[Code]=$C9)*(ST[Customer Name]=BN$3), ""), 1), IF(_xlpm.result=0, "", _xlpm.result) ), "")} | BV9: =IFERROR(IF(CEILING(BU9 + (BU9 * $N$2), 1) = 0, "", CEILING(BU9 + (BU9 * $N$2), 1))*$B$3, "") | BW9: =IFERROR((BV9*BP9),"") | BX9: =IFERROR((BV9*BQ9),"") | BZ9: {=IFERROR(_xlfn._xlws.FILTER(#REF!,(#REF!=$C9) * (#REF!=BZ$3),"" ),"")} | CA9: {=IFERROR(_xlfn.XLOOKUP($C9,Master_Price_Level_NZ[Code],INDEX(Master_Price_Level_NZ[], , MATCH('Promo Form'!BZ$3, Master_Price_Level_NZ[#Headers], 0))),"")} | CB9: =IFERROR(((CA9*(1-BZ$2))*$CN9)*BZ$39,"") | CC9: =IFERROR(((CA9*(1-BZ$2))*$CN9)*BZ$38,"") | CD9: =IFERROR(IF(CB9+CC9=0,"",CB9+CC9),"") | CE9: =IFERROR((($CL9/1.15)-(CA9-(CA9*BZ$2)))/($CL9/1.15),"") | CF9: =IFERROR((($CM9/1.15)+(CB9+CC9)-(CA9-(CA9*BZ$2)))/($CM9/1.15),"") | CG9: {=IFERROR( _xlfn.LET( _xlpm.result, INDEX(_xlfn._xlws.FILTER(ST[6wk avg], (ST[Code]=$C9)*(ST[Customer Name]=BZ$3), ""), 1), IF(_xlpm.result=0, "", _xlpm.result) ), "")} | CH9: =IFERROR(IF(CEILING(CG9 + (CG9 * $N$2), 1) = 0, "", CEILING(CG9 + (CG9 * $N$2), 1))*$B$3, "") | CI9: =IFERROR((CH9*CB9),"") | CJ9: =IFERROR((CH9*CC9),"") | CL9: =IFERROR(_xlfn.XLOOKUP(C9,Master_Price_Level_NZ[Code],Master_Price_Level_NZ[Base (RRP Inc)]),"") | CM9: =IFERROR(CL9-(CL9*CN9),"") | CN9: =IF(C9="", "",CN8) | CO9: =IFERROR((CL9-CM9),"")
A10: =IF(C10="","",A9) | B10: =IF(C10="","",B9) | D10: =IF(C10="", "",_xlfn.XLOOKUP(C10,'Master Price Level NZ'!B:B,'Master Price Level NZ'!C:C)) | G10: {=IFERROR(_xlfn.XLOOKUP($C10,Master_Price_Level_NZ[Code],INDEX(Master_Price_Level_NZ[], , MATCH('Promo Form'!F$3, Master_Price_Level_NZ[#Headers], 0))),"")} | H10: =IFERROR(((G10*(1-F$2))*$CN10)*F$39,"") | I10: =IFERROR(((G10*(1-F$2))*$CN10)*F$38,"") | J10: =IFERROR(IF(H10+I10=0,"",H10+I10),"") | K10: =IFERROR((($CL10/1.15)-(G10-(G10*F$2)))/($CL10/1.15),"") | L10: =IFERROR((($CM10/1.15)+(H10+I10)-(G10-(G10*F$2)))/($CM10/1.15),"") | M10: {=IF($C10="","",IFERROR(_xlfn._xlws.FILTER(ST[6wk avg],(ST[Code]=$C10)*(ST[Customer Name]=F$3),""),""))} | N10: =IFERROR(IF(CEILING(M10 + (M10 * $N$2), 1) = 0, "", CEILING(M10 + (M10 * $N$2), 1))*$B$3, "") | O10: =IFERROR((N10*H10),"") | P10: =IFERROR((N10*I10),"") | R10: {=IFERROR(_xlfn._xlws.FILTER(#REF!,(#REF!=$C10) * (#REF!=R$3),"" ),"")} | S10: {=IFERROR(_xlfn.XLOOKUP($C10,Master_Price_Level_NZ[Code],INDEX(Master_Price_Level_NZ[], , MATCH('Promo Form'!R$3, Master_Price_Level_NZ[#Headers], 0))),"")} | T10: =IFERROR(((S10*(1-R$2))*$CN10)*R$39,"") | U10: =IFERROR(((S10*(1-R$2))*$CN10)*R$38,"") | V10: =IFERROR(IF(T10+U10=0,"",T10+U10),"") | W10: =IFERROR((($CL10/1.15)-(S10-(S10*R$2)))/($CL10/1.15),"") | X10: =IFERROR((($CM10/1.15)+(T10+U10)-(S10-(S10*R$2)))/($CM10/1.15),"") | Y10: {=IFERROR( _xlfn.LET( _xlpm.result, INDEX(_xlfn._xlws.FILTER(ST[6wk avg], (ST[Code]=$C10)*(ST[Customer Name]=R$3), ""), 1), IF(_xlpm.result=0, "", _xlpm.result) ), "")} | Z10: =IFERROR(IF(CEILING(Y10 + (Y10 * $N$2), 1) = 0, "", CEILING(Y10 + (Y10 * $N$2), 1))*$B$3, "") | AA10: =IFERROR((Z10*T10),"") | AB10: =IFERROR((Z10*U10),"") | AD10: {=IFERROR(_xlfn._xlws.FILTER(#REF!,(#REF!=$C10) * (#REF!=AD$3),"" ),"")} | AE10: {=IFERROR(_xlfn.XLOOKUP($C10,Master_Price_Level_NZ[Code],INDEX(Master_Price_Level_NZ[], , MATCH('Promo Form'!AD$3, Master_Price_Level_NZ[#Headers], 0))),"")} | AF10: =IFERROR(((AE10*(1-AD$2))*$CN10)*AD$39,"") | AG10: =IFERROR(((AE10*(1-AD$2))*$CN10)*AD$38,"") | AH10: =IFERROR(IF(AF10+AG10=0,"",AF10+AG10),"") | AI10: =IFERROR((($CL10/1.15)-(AE10-(AE10*AD$2)))/($CL10/1.15),"") | AJ10: =IFERROR((($CM10/1.15)+(AF10+AG10)-(AE10-(AE10*AD$2)))/($CM10/1.15),"") | AK10: {=IFERROR( _xlfn.LET( _xlpm.result, INDEX(_xlfn._xlws.FILTER(ST[6wk avg], (ST[Code]=$C10)*(ST[Customer Name]=AD$3), ""), 1), IF(_xlpm.result=0, "", _xlpm.result) ), "")} | AL10: =IFERROR(IF(CEILING(AK10 + (AK10 * $N$2), 1) = 0, "", CEILING(AK10 + (AK10 * $N$2), 1))*$B$3, "") | AM10: =IFERROR((AL10*AF10),"") | AN10: =IFERROR((AL10*AG10),"") | AP10: {=IFERROR(_xlfn._xlws.FILTER(#REF!,(#REF!=$C10) * (#REF!=AP$3),"" ),"")} | AQ10: {=IFERROR(_xlfn.XLOOKUP($C10,Master_Price_Level_NZ[Code],INDEX(Master_Price_Level_NZ[], , MATCH('Promo Form'!AP$3, Master_Price_Level_NZ[#Headers], 0))),"")} | AR10: =IFERROR(((AQ10*(1-AP$2))*$CN10)*AP$39,"") | AS10: =IFERROR(((AQ10*(1-AP$2))*$CN10)*AP$38,"") | AT10: =IFERROR(IF(AR10+AS10=0,"",AR10+AS10),"") | AU10: =IFERROR((($CL10/1.15)-(AQ10-(AQ10*AP$2)))/($CL10/1.15),"") | AV10: =IFERROR((($CM10/1.15)+(AR10+AS10)-(AQ10-(AQ10*AP$2)))/($CM10/1.15),"") | AW10: {=IFERROR( _xlfn.LET( _xlpm.result, INDEX(_xlfn._xlws.FILTER(ST[6wk avg], (ST[Code]=$C10)*(ST[Customer Name]=AP$3), ""), 1), IF(_xlpm.result=0, "", _xlpm.result) ), "")} | AX10: =IFERROR(IF(CEILING(AW10 + (AW10 * $N$2), 1) = 0, "", CEILING(AW10 + (AW10 * $N$2), 1))*$B$3, "") | AY10: =IFERROR((AX10*AR10),"") | AZ10: =IFERROR((AX10*AS10),"") | BB10: {=IFERROR(_xlfn._xlws.FILTER(#REF!,(#REF!=$C10) * (#REF!=BB$3),"" ),"")} | BC10: {=IFERROR(_xlfn.XLOOKUP($C10,Master_Price_Level_NZ[Code],INDEX(Master_Price_Level_NZ[], , MATCH('Promo Form'!BB$3, Master_Price_Level_NZ[#Headers], 0))),"")} | BD10: =IFERROR(((BC10*(1-BB$2))*$CN10)*BB$39,"") | BE10: =IFERROR(((BC10*(1-BB$2))*$CN10)*BB$38,"") | BF10: =IFERROR(IF(BD10+BE10=0,"",BD10+BE10),"") | BG10: =IFERROR((($CL10/1.15)-(BC10-(BC10*BB$2)))/($CL10/1.15),"") | BH10: =IFERROR((($CM10/1.15)+(BD10+BE10)-(BC10-(BC10*BB$2)))/($CM10/1.15),"") | BI10: {=IFERROR( _xlfn.LET( _xlpm.result, INDEX(_xlfn._xlws.FILTER(ST[6wk avg], (ST[Code]=$C10)*(ST[Customer Name]=BB$3), ""), 1), IF(_xlpm.result=0, "", _xlpm.result) ), "")} | BJ10: =IFERROR(IF(CEILING(BI10 + (BI10 * $N$2), 1) = 0, "", CEILING(BI10 + (BI10 * $N$2), 1))*$B$3, "") | BK10: =IFERROR((BJ10*BD10),"") | BL10: =IFERROR((BJ10*BE10),"") | BN10: {=IFERROR(_xlfn._xlws.FILTER(#REF!,(#REF!=$C10) * (#REF!=BN$3),"" ),"")} | BO10: {=IFERROR(_xlfn.XLOOKUP($C10,Master_Price_Level_NZ[Code],INDEX(Master_Price_Level_NZ[], , MATCH('Promo Form'!BN$3, Master_Price_Level_NZ[#Headers], 0))),"")} | BP10: =IFERROR(((BO10*(1-BN$2))*$CN10)*BN$39,"") | BQ10: =IFERROR(((BO10*(1-BN$2))*$CN10)*BN$38,"") | BR10: =IFERROR(IF(BP10+BQ10=0,"",BP10+BQ10),"") | BS10: =IFERROR((($CL10/1.15)-(BO10-(BO10*BN$2)))/($CL10/1.15),"") | BT10: =IFERROR((($CM10/1.15)+(BP10+BQ10)-(BO10-(BO10*BN$2)))/($CM10/1.15),"") | BU10: {=IFERROR( _xlfn.LET( _xlpm.result, INDEX(_xlfn._xlws.FILTER(ST[6wk avg], (ST[Code]=$C10)*(ST[Customer Name]=BN$3), ""), 1), IF(_xlpm.result=0, "", _xlpm.result) ), "")} | BV10: =IFERROR(IF(CEILING(BU10 + (BU10 * $N$2), 1) = 0, "", CEILING(BU10 + (BU10 * $N$2), 1))*$B$3, "") | BW10: =IFERROR((BV10*BP10),"") | BX10: =IFERROR((BV10*BQ10),"") | BZ10: {=IFERROR(_xlfn._xlws.FILTER(#REF!,(#REF!=$C10) * (#REF!=BZ$3),"" ),"")} | CA10: {=IFERROR(_xlfn.XLOOKUP($C10,Master_Price_Level_NZ[Code],INDEX(Master_Price_Level_NZ[], , MATCH('Promo Form'!BZ$3, Master_Price_Level_NZ[#Headers], 0))),"")} | CB10: =IFERROR(((CA10*(1-BZ$2))*$CN10)*BZ$39,"") | CC10: =IFERROR(((CA10*(1-BZ$2))*$CN10)*BZ$38,"") | CD10: =IFERROR(IF(CB10+CC10=0,"",CB10+CC10),"") | CE10: =IFERROR((($CL10/1.15)-(CA10-(CA10*BZ$2)))/($CL10/1.15),"") | CF10: =IFERROR((($CM10/1.15)+(CB10+CC10)-(CA10-(CA10*BZ$2)))/($CM10/1.15),"") | CG10: {=IFERROR( _xlfn.LET( _xlpm.result, INDEX(_xlfn._xlws.FILTER(ST[6wk avg], (ST[Code]=$C10)*(ST[Customer Name]=BZ$3), ""), 1), IF(_xlpm.result=0, "", _xlpm.result) ), "")} | CH10: =IFERROR(IF(CEILING(CG10 + (CG10 * $N$2), 1) = 0, "", CEILING(CG10 + (CG10 * $N$2), 1))*$B$3, "") | CI10: =IFERROR((CH10*CB10),"") | CJ10: =IFERROR((CH10*CC10),"") | CL10: =IFERROR(_xlfn.XLOOKUP(C10,Master_Price_Level_NZ[Code],Master_Price_Level_NZ[Base (RRP Inc)]),"") | CM10: =IFERROR(CL10-(CL10*CN10),"") | CN10: =IF(C10="", "",CN9) | CO10: =IFERROR((CL10-CM10),"")
A11: =IF(C11="","",A10) | B11: =IF(C11="","",B10) | D11: =IF(C11="", "",_xlfn.XLOOKUP(C11,'Master Price Level NZ'!B:B,'Master Price Level NZ'!C:C)) | G11: {=IFERROR(_xlfn.XLOOKUP($C11,Master_Price_Level_NZ[Code],INDEX(Master_Price_Level_NZ[], , MATCH('Promo Form'!F$3, Master_Price_Level_NZ[#Headers], 0))),"")} | H11: =IFERROR(((G11*(1-F$2))*$CN11)*F$39,"") | I11: =IFERROR(((G11*(1-F$2))*$CN11)*F$38,"") | J11: =IFERROR(IF(H11+I11=0,"",H11+I11),"") | K11: =IFERROR((($CL11/1.15)-(G11-(G11*F$2)))/($CL11/1.15),"") | L11: =IFERROR((($CM11/1.15)+(H11+I11)-(G11-(G11*F$2)))/($CM11/1.15),"") | M11: {=IF($C11="","",IFERROR(_xlfn._xlws.FILTER(ST[6wk avg],(ST[Code]=$C11)*(ST[Customer Name]=F$3),""),""))} | N11: =IFERROR(IF(CEILING(M11 + (M11 * $N$2), 1) = 0, "", CEILING(M11 + (M11 * $N$2), 1))*$B$3, "") | O11: =IFERROR((N11*H11),"") | P11: =IFERROR((N11*I11),"") | R11: {=IFERROR(_xlfn._xlws.FILTER(#REF!,(#REF!=$C11) * (#REF!=R$3),"" ),"")} | S11: {=IFERROR(_xlfn.XLOOKUP($C11,Master_Price_Level_NZ[Code],INDEX(Master_Price_Level_NZ[], , MATCH('Promo Form'!R$3, Master_Price_Level_NZ[#Headers], 0))),"")} | T11: =IFERROR(((S11*(1-R$2))*$CN11)*R$39,"") | U11: =IFERROR(((S11*(1-R$2))*$CN11)*R$38,"") | V11: =IFERROR(IF(T11+U11=0,"",T11+U11),"") | W11: =IFERROR((($CL11/1.15)-(S11-(S11*R$2)))/($CL11/1.15),"") | X11: =IFERROR((($CM11/1.15)+(T11+U11)-(S11-(S11*R$2)))/($CM11/1.15),"") | Y11: {=IFERROR( _xlfn.LET( _xlpm.result, INDEX(_xlfn._xlws.FILTER(ST[6wk avg], (ST[Code]=$C11)*(ST[Customer Name]=R$3), ""), 1), IF(_xlpm.result=0, "", _xlpm.result) ), "")} | Z11: =IFERROR(IF(CEILING(Y11 + (Y11 * $N$2), 1) = 0, "", CEILING(Y11 + (Y11 * $N$2), 1))*$B$3, "") | AA11: =IFERROR((Z11*T11),"") | AB11: =IFERROR((Z11*U11),"") | AD11: {=IFERROR(_xlfn._xlws.FILTER(#REF!,(#REF!=$C11) * (#REF!=AD$3),"" ),"")} | AE11: {=IFERROR(_xlfn.XLOOKUP($C11,Master_Price_Level_NZ[Code],INDEX(Master_Price_Level_NZ[], , MATCH('Promo Form'!AD$3, Master_Price_Level_NZ[#Headers], 0))),"")} | AF11: =IFERROR(((AE11*(1-AD$2))*$CN11)*AD$39,"") | AG11: =IFERROR(((AE11*(1-AD$2))*$CN11)*AD$38,"") | AH11: =IFERROR(IF(AF11+AG11=0,"",AF11+AG11),"") | AI11: =IFERROR((($CL11/1.15)-(AE11-(AE11*AD$2)))/($CL11/1.15),"") | AJ11: =IFERROR((($CM11/1.15)+(AF11+AG11)-(AE11-(AE11*AD$2)))/($CM11/1.15),"") | AK11: {=IFERROR( _xlfn.LET( _xlpm.result, INDEX(_xlfn._xlws.FILTER(ST[6wk avg], (ST[Code]=$C11)*(ST[Customer Name]=AD$3), ""), 1), IF(_xlpm.result=0, "", _xlpm.result) ), "")} | AL11: =IFERROR(IF(CEILING(AK11 + (AK11 * $N$2), 1) = 0, "", CEILING(AK11 + (AK11 * $N$2), 1))*$B$3, "") | AM11: =IFERROR((AL11*AF11),"") | AN11: =IFERROR((AL11*AG11),"") | AP11: {=IFERROR(_xlfn._xlws.FILTER(#REF!,(#REF!=$C11) * (#REF!=AP$3),"" ),"")} | AQ11: {=IFERROR(_xlfn.XLOOKUP($C11,Master_Price_Level_NZ[Code],INDEX(Master_Price_Level_NZ[], , MATCH('Promo Form'!AP$3, Master_Price_Level_NZ[#Headers], 0))),"")} | AR11: =IFERROR(((AQ11*(1-AP$2))*$CN11)*AP$39,"") | AS11: =IFERROR(((AQ11*(1-AP$2))*$CN11)*AP$38,"") | AT11: =IFERROR(IF(AR11+AS11=0,"",AR11+AS11),"") | AU11: =IFERROR((($CL11/1.15)-(AQ11-(AQ11*AP$2)))/($CL11/1.15),"") | AV11: =IFERROR((($CM11/1.15)+(AR11+AS11)-(AQ11-(AQ11*AP$2)))/($CM11/1.15),"") | AW11: {=IFERROR( _xlfn.LET( _xlpm.result, INDEX(_xlfn._xlws.FILTER(ST[6wk avg], (ST[Code]=$C11)*(ST[Customer Name]=AP$3), ""), 1), IF(_xlpm.result=0, "", _xlpm.result) ), "")} | AX11: =IFERROR(IF(CEILING(AW11 + (AW11 * $N$2), 1) = 0, "", CEILING(AW11 + (AW11 * $N$2), 1))*$B$3, "") | AY11: =IFERROR((AX11*AR11),"") | AZ11: =IFERROR((AX11*AS11),"") | BB11: {=IFERROR(_xlfn._xlws.FILTER(#REF!,(#REF!=$C11) * (#REF!=BB$3),"" ),"")} | BC11: {=IFERROR(_xlfn.XLOOKUP($C11,Master_Price_Level_NZ[Code],INDEX(Master_Price_Level_NZ[], , MATCH('Promo Form'!BB$3, Master_Price_Level_NZ[#Headers], 0))),"")} | BD11: =IFERROR(((BC11*(1-BB$2))*$CN11)*BB$39,"") | BE11: =IFERROR(((BC11*(1-BB$2))*$CN11)*BB$38,"") | BF11: =IFERROR(IF(BD11+BE11=0,"",BD11+BE11),"") | BG11: =IFERROR((($CL11/1.15)-(BC11-(BC11*BB$2)))/($CL11/1.15),"") | BH11: =IFERROR((($CM11/1.15)+(BD11+BE11)-(BC11-(BC11*BB$2)))/($CM11/1.15),"") | BI11: {=IFERROR( _xlfn.LET( _xlpm.result, INDEX(_xlfn._xlws.FILTER(ST[6wk avg], (ST[Code]=$C11)*(ST[Customer Name]=BB$3), ""), 1), IF(_xlpm.result=0, "", _xlpm.result) ), "")} | BJ11: =IFERROR(IF(CEILING(BI11 + (BI11 * $N$2), 1) = 0, "", CEILING(BI11 + (BI11 * $N$2), 1))*$B$3, "") | BK11: =IFERROR((BJ11*BD11),"") | BL11: =IFERROR((BJ11*BE11),"") | BN11: {=IFERROR(_xlfn._xlws.FILTER(#REF!,(#REF!=$C11) * (#REF!=BN$3),"" ),"")} | BO11: {=IFERROR(_xlfn.XLOOKUP($C11,Master_Price_Level_NZ[Code],INDEX(Master_Price_Level_NZ[], , MATCH('Promo Form'!BN$3, Master_Price_Level_NZ[#Headers], 0))),"")} | BP11: =IFERROR(((BO11*(1-BN$2))*$CN11)*BN$39,"") | BQ11: =IFERROR(((BO11*(1-BN$2))*$CN11)*BN$38,"") | BR11: =IFERROR(IF(BP11+BQ11=0,"",BP11+BQ11),"") | BS11: =IFERROR((($CL11/1.15)-(BO11-(BO11*BN$2)))/($CL11/1.15),"") | BT11: =IFERROR((($CM11/1.15)+(BP11+BQ11)-(BO11-(BO11*BN$2)))/($CM11/1.15),"") | BU11: {=IFERROR( _xlfn.LET( _xlpm.result, INDEX(_xlfn._xlws.FILTER(ST[6wk avg], (ST[Code]=$C11)*(ST[Customer Name]=BN$3), ""), 1), IF(_xlpm.result=0, "", _xlpm.result) ), "")} | BV11: =IFERROR(IF(CEILING(BU11 + (BU11 * $N$2), 1) = 0, "", CEILING(BU11 + (BU11 * $N$2), 1))*$B$3, "") | BW11: =IFERROR((BV11*BP11),"") | BX11: =IFERROR((BV11*BQ11),"") | BZ11: {=IFERROR(_xlfn._xlws.FILTER(#REF!,(#REF!=$C11) * (#REF!=BZ$3),"" ),"")} | CA11: {=IFERROR(_xlfn.XLOOKUP($C11,Master_Price_Level_NZ[Code],INDEX(Master_Price_Level_NZ[], , MATCH('Promo Form'!BZ$3, Master_Price_Level_NZ[#Headers], 0))),"")} | CB11: =IFERROR(((CA11*(1-BZ$2))*$CN11)*BZ$39,"") | CC11: =IFERROR(((CA11*(1-BZ$2))*$CN11)*BZ$38,"") | CD11: =IFERROR(IF(CB11+CC11=0,"",CB11+CC11),"") | CE11: =IFERROR((($CL11/1.15)-(CA11-(CA11*BZ$2)))/($CL11/1.15),"") | CF11: =IFERROR((($CM11/1.15)+(CB11+CC11)-(CA11-(CA11*BZ$2)))/($CM11/1.15),"") | CG11: {=IFERROR( _xlfn.LET( _xlpm.result, INDEX(_xlfn._xlws.FILTER(ST[6wk avg], (ST[Code]=$C11)*(ST[Customer Name]=BZ$3), ""), 1), IF(_xlpm.result=0, "", _xlpm.result) ), "")} | CH11: =IFERROR(IF(CEILING(CG11 + (CG11 * $N$2), 1) = 0, "", CEILING(CG11 + (CG11 * $N$2), 1))*$B$3, "") | CI11: =IFERROR((CH11*CB11),"") | CJ11: =IFERROR((CH11*CC11),"") | CL11: =IFERROR(_xlfn.XLOOKUP(C11,Master_Price_Level_NZ[Code],Master_Price_Level_NZ[Base (RRP Inc)]),"") | CM11: =IFERROR(CL11-(CL11*CN11),"") | CN11: =IF(C11="", "",CN10) | CO11: =IFERROR((CL11-CM11),"")
A12: =IF(C12="","",A11) | B12: =IF(C12="","",B11) | D12: =IF(C12="", "",_xlfn.XLOOKUP(C12,'Master Price Level NZ'!B:B,'Master Price Level NZ'!C:C)) | G12: {=IFERROR(_xlfn.XLOOKUP($C12,Master_Price_Level_NZ[Code],INDEX(Master_Price_Level_NZ[], , MATCH('Promo Form'!F$3, Master_Price_Level_NZ[#Headers], 0))),"")} | H12: =IFERROR(((G12*(1-F$2))*$CN12)*F$39,"") | I12: =IFERROR(((G12*(1-F$2))*$CN12)*F$38,"") | J12: =IFERROR(IF(H12+I12=0,"",H12+I12),"") | K12: =IFERROR((($CL12/1.15)-(G12-(G12*F$2)))/($CL12/1.15),"") | L12: =IFERROR((($CM12/1.15)+(H12+I12)-(G12-(G12*F$2)))/($CM12/1.15),"") | M12: {=IF($C12="","",IFERROR(_xlfn._xlws.FILTER(ST[6wk avg],(ST[Code]=$C12)*(ST[Customer Name]=F$3),""),""))} | N12: =IFERROR(IF(CEILING(M12 + (M12 * $N$2), 1) = 0, "", CEILING(M12 + (M12 * $N$2), 1))*$B$3, "") | O12: =IFERROR((N12*H12),"") | P12: =IFERROR((N12*I12),"") | R12: {=IFERROR(_xlfn._xlws.FILTER(#REF!,(#REF!=$C12) * (#REF!=R$3),"" ),"")} | S12: {=IFERROR(_xlfn.XLOOKUP($C12,Master_Price_Level_NZ[Code],INDEX(Master_Price_Level_NZ[], , MATCH('Promo Form'!R$3, Master_Price_Level_NZ[#Headers], 0))),"")} | T12: =IFERROR(((S12*(1-R$2))*$CN12)*R$39,"") | U12: =IFERROR(((S12*(1-R$2))*$CN12)*R$38,"") | V12: =IFERROR(IF(T12+U12=0,"",T12+U12),"") | W12: =IFERROR((($CL12/1.15)-(S12-(S12*R$2)))/($CL12/1.15),"") | X12: =IFERROR((($CM12/1.15)+(T12+U12)-(S12-(S12*R$2)))/($CM12/1.15),"") | Y12: {=IFERROR( _xlfn.LET( _xlpm.result, INDEX(_xlfn._xlws.FILTER(ST[6wk avg], (ST[Code]=$C12)*(ST[Customer Name]=R$3), ""), 1), IF(_xlpm.result=0, "", _xlpm.result) ), "")} | Z12: =IFERROR(IF(CEILING(Y12 + (Y12 * $N$2), 1) = 0, "", CEILING(Y12 + (Y12 * $N$2), 1))*$B$3, "") | AA12: =IFERROR((Z12*T12),"") | AB12: =IFERROR((Z12*U12),"") | AD12: {=IFERROR(_xlfn._xlws.FILTER(#REF!,(#REF!=$C12) * (#REF!=AD$3),"" ),"")} | AE12: {=IFERROR(_xlfn.XLOOKUP($C12,Master_Price_Level_NZ[Code],INDEX(Master_Price_Level_NZ[], , MATCH('Promo Form'!AD$3, Master_Price_Level_NZ[#Headers], 0))),"")} | AF12: =IFERROR(((AE12*(1-AD$2))*$CN12)*AD$39,"") | AG12: =IFERROR(((AE12*(1-AD$2))*$CN12)*AD$38,"") | AH12: =IFERROR(IF(AF12+AG12=0,"",AF12+AG12),"") | AI12: =IFERROR((($CL12/1.15)-(AE12-(AE12*AD$2)))/($CL12/1.15),"") | AJ12: =IFERROR((($CM12/1.15)+(AF12+AG12)-(AE12-(AE12*AD$2)))/($CM12/1.15),"") | AK12: {=IFERROR( _xlfn.LET( _xlpm.result, INDEX(_xlfn._xlws.FILTER(ST[6wk avg], (ST[Code]=$C12)*(ST[Customer Name]=AD$3), ""), 1), IF(_xlpm.result=0, "", _xlpm.result) ), "")} | AL12: =IFERROR(IF(CEILING(AK12 + (AK12 * $N$2), 1) = 0, "", CEILING(AK12 + (AK12 * $N$2), 1))*$B$3, "") | AM12: =IFERROR((AL12*AF12),"") | AN12: =IFERROR((AL12*AG12),"") | AP12: {=IFERROR(_xlfn._xlws.FILTER(#REF!,(#REF!=$C12) * (#REF!=AP$3),"" ),"")} | AQ12: {=IFERROR(_xlfn.XLOOKUP($C12,Master_Price_Level_NZ[Code],INDEX(Master_Price_Level_NZ[], , MATCH('Promo Form'!AP$3, Master_Price_Level_NZ[#Headers], 0))),"")} | AR12: =IFERROR(((AQ12*(1-AP$2))*$CN12)*AP$39,"") | AS12: =IFERROR(((AQ12*(1-AP$2))*$CN12)*AP$38,"") | AT12: =IFERROR(IF(AR12+AS12=0,"",AR12+AS12),"") | AU12: =IFERROR((($CL12/1.15)-(AQ12-(AQ12*AP$2)))/($CL12/1.15),"") | AV12: =IFERROR((($CM12/1.15)+(AR12+AS12)-(AQ12-(AQ12*AP$2)))/($CM12/1.15),"") | AW12: {=IFERROR( _xlfn.LET( _xlpm.result, INDEX(_xlfn._xlws.FILTER(ST[6wk avg], (ST[Code]=$C12)*(ST[Customer Name]=AP$3), ""), 1), IF(_xlpm.result=0, "", _xlpm.result) ), "")} | AX12: =IFERROR(IF(CEILING(AW12 + (AW12 * $N$2), 1) = 0, "", CEILING(AW12 + (AW12 * $N$2), 1))*$B$3, "") | AY12: =IFERROR((AX12*AR12),"") | AZ12: =IFERROR((AX12*AS12),"") | BB12: {=IFERROR(_xlfn._xlws.FILTER(#REF!,(#REF!=$C12) * (#REF!=BB$3),"" ),"")} | BC12: {=IFERROR(_xlfn.XLOOKUP($C12,Master_Price_Level_NZ[Code],INDEX(Master_Price_Level_NZ[], , MATCH('Promo Form'!BB$3, Master_Price_Level_NZ[#Headers], 0))),"")} | BD12: =IFERROR(((BC12*(1-BB$2))*$CN12)*BB$39,"") | BE12: =IFERROR(((BC12*(1-BB$2))*$CN12)*BB$38,"") | BF12: =IFERROR(IF(BD12+BE12=0,"",BD12+BE12),"") | BG12: =IFERROR((($CL12/1.15)-(BC12-(BC12*BB$2)))/($CL12/1.15),"") | BH12: =IFERROR((($CM12/1.15)+(BD12+BE12)-(BC12-(BC12*BB$2)))/($CM12/1.15),"") | BI12: {=IFERROR( _xlfn.LET( _xlpm.result, INDEX(_xlfn._xlws.FILTER(ST[6wk avg], (ST[Code]=$C12)*(ST[Customer Name]=BB$3), ""), 1), IF(_xlpm.result=0, "", _xlpm.result) ), "")} | BJ12: =IFERROR(IF(CEILING(BI12 + (BI12 * $N$2), 1) = 0, "", CEILING(BI12 + (BI12 * $N$2), 1))*$B$3, "") | BK12: =IFERROR((BJ12*BD12),"") | BL12: =IFERROR((BJ12*BE12),"") | BN12: {=IFERROR(_xlfn._xlws.FILTER(#REF!,(#REF!=$C12) * (#REF!=BN$3),"" ),"")} | BO12: {=IFERROR(_xlfn.XLOOKUP($C12,Master_Price_Level_NZ[Code],INDEX(Master_Price_Level_NZ[], , MATCH('Promo Form'!BN$3, Master_Price_Level_NZ[#Headers], 0))),"")} | BP12: =IFERROR(((BO12*(1-BN$2))*$CN12)*BN$39,"") | BQ12: =IFERROR(((BO12*(1-BN$2))*$CN12)*BN$38,"") | BR12: =IFERROR(IF(BP12+BQ12=0,"",BP12+BQ12),"") | BS12: =IFERROR((($CL12/1.15)-(BO12-(BO12*BN$2)))/($CL12/1.15),"") | BT12: =IFERROR((($CM12/1.15)+(BP12+BQ12)-(BO12-(BO12*BN$2)))/($CM12/1.15),"") | BU12: {=IFERROR( _xlfn.LET( _xlpm.result, INDEX(_xlfn._xlws.FILTER(ST[6wk avg], (ST[Code]=$C12)*(ST[Customer Name]=BN$3), ""), 1), IF(_xlpm.result=0, "", _xlpm.result) ), "")} | BV12: =IFERROR(IF(CEILING(BU12 + (BU12 * $N$2), 1) = 0, "", CEILING(BU12 + (BU12 * $N$2), 1))*$B$3, "") | BW12: =IFERROR((BV12*BP12),"") | BX12: =IFERROR((BV12*BQ12),"") | BZ12: {=IFERROR(_xlfn._xlws.FILTER(#REF!,(#REF!=$C12) * (#REF!=BZ$3),"" ),"")} | CA12: {=IFERROR(_xlfn.XLOOKUP($C12,Master_Price_Level_NZ[Code],INDEX(Master_Price_Level_NZ[], , MATCH('Promo Form'!BZ$3, Master_Price_Level_NZ[#Headers], 0))),"")} | CB12: =IFERROR(((CA12*(1-BZ$2))*$CN12)*BZ$39,"") | CC12: =IFERROR(((CA12*(1-BZ$2))*$CN12)*BZ$38,"") | CD12: =IFERROR(IF(CB12+CC12=0,"",CB12+CC12),"") | CE12: =IFERROR((($CL12/1.15)-(CA12-(CA12*BZ$2)))/($CL12/1.15),"") | CF12: =IFERROR((($CM12/1.15)+(CB12+CC12)-(CA12-(CA12*BZ$2)))/($CM12/1.15),"") | CG12: {=IFERROR( _xlfn.LET( _xlpm.result, INDEX(_xlfn._xlws.FILTER(ST[6wk avg], (ST[Code]=$C12)*(ST[Customer Name]=BZ$3), ""), 1), IF(_xlpm.result=0, "", _xlpm.result) ), "")} | CH12: =IFERROR(IF(CEILING(CG12 + (CG12 * $N$2), 1) = 0, "", CEILING(CG12 + (CG12 * $N$2), 1))*$B$3, "") | CI12: =IFERROR((CH12*CB12),"") | CJ12: =IFERROR((CH12*CC12),"") | CL12: =IFERROR(_xlfn.XLOOKUP(C12,Master_Price_Level_NZ[Code],Master_Price_Level_NZ[Base (RRP Inc)]),"") | CM12: =IFERROR(CL12-(CL12*CN12),"") | CN12: =IF(C12="", "",CN11) | CO12: =IFERROR((CL12-CM12),"")
A13: =IF(C13="","",A12) | B13: =IF(C13="","",B12) | D13: =IF(C13="", "",_xlfn.XLOOKUP(C13,'Master Price Level NZ'!B:B,'Master Price Level NZ'!C:C)) | G13: {=IFERROR(_xlfn.XLOOKUP($C13,Master_Price_Level_NZ[Code],INDEX(Master_Price_Level_NZ[], , MATCH('Promo Form'!F$3, Master_Price_Level_NZ[#Headers], 0))),"")} | H13: =IFERROR(((G13*(1-F$2))*$CN13)*F$39,"") | I13: =IFERROR(((G13*(1-F$2))*$CN13)*F$38,"") | J13: =IFERROR(IF(H13+I13=0,"",H13+I13),"") | K13: =IFERROR((($CL13/1.15)-(G13-(G13*F$2)))/($CL13/1.15),"") | L13: =IFERROR((($CM13/1.15)+(H13+I13)-(G13-(G13*F$2)))/($CM13/1.15),"") | M13: {=IF($C13="","",IFERROR(_xlfn._xlws.FILTER(ST[6wk avg],(ST[Code]=$C13)*(ST[Customer Name]=F$3),""),""))} | N13: =IFERROR(IF(CEILING(M13 + (M13 * $N$2), 1) = 0, "", CEILING(M13 + (M13 * $N$2), 1))*$B$3, "") | O13: =IFERROR((N13*H13),"") | P13: =IFERROR((N13*I13),"") | R13: {=IFERROR(_xlfn._xlws.FILTER(#REF!,(#REF!=$C13) * (#REF!=R$3),"" ),"")} | S13: {=IFERROR(_xlfn.XLOOKUP($C13,Master_Price_Level_NZ[Code],INDEX(Master_Price_Level_NZ[], , MATCH('Promo Form'!R$3, Master_Price_Level_NZ[#Headers], 0))),"")} | T13: =IFERROR(((S13*(1-R$2))*$CN13)*R$39,"") | U13: =IFERROR(((S13*(1-R$2))*$CN13)*R$38,"") | V13: =IFERROR(IF(T13+U13=0,"",T13+U13),"") | W13: =IFERROR((($CL13/1.15)-(S13-(S13*R$2)))/($CL13/1.15),"") | X13: =IFERROR((($CM13/1.15)+(T13+U13)-(S13-(S13*R$2)))/($CM13/1.15),"") | Y13: {=IFERROR( _xlfn.LET( _xlpm.result, INDEX(_xlfn._xlws.FILTER(ST[6wk avg], (ST[Code]=$C13)*(ST[Customer Name]=R$3), ""), 1), IF(_xlpm.result=0, "", _xlpm.result) ), "")} | Z13: =IFERROR(IF(CEILING(Y13 + (Y13 * $N$2), 1) = 0, "", CEILING(Y13 + (Y13 * $N$2), 1))*$B$3, "") | AA13: =IFERROR((Z13*T13),"") | AB13: =IFERROR((Z13*U13),"") | AD13: {=IFERROR(_xlfn._xlws.FILTER(#REF!,(#REF!=$C13) * (#REF!=AD$3),"" ),"")} | AE13: {=IFERROR(_xlfn.XLOOKUP($C13,Master_Price_Level_NZ[Code],INDEX(Master_Price_Level_NZ[], , MATCH('Promo Form'!AD$3, Master_Price_Level_NZ[#Headers], 0))),"")} | AF13: =IFERROR(((AE13*(1-AD$2))*$CN13)*AD$39,"") | AG13: =IFERROR(((AE13*(1-AD$2))*$CN13)*AD$38,"") | AH13: =IFERROR(IF(AF13+AG13=0,"",AF13+AG13),"") | AI13: =IFERROR((($CL13/1.15)-(AE13-(AE13*AD$2)))/($CL13/1.15),"") | AJ13: =IFERROR((($CM13/1.15)+(AF13+AG13)-(AE13-(AE13*AD$2)))/($CM13/1.15),"") | AK13: {=IFERROR( _xlfn.LET( _xlpm.result, INDEX(_xlfn._xlws.FILTER(ST[6wk avg], (ST[Code]=$C13)*(ST[Customer Name]=AD$3), ""), 1), IF(_xlpm.result=0, "", _xlpm.result) ), "")} | AL13: =IFERROR(IF(CEILING(AK13 + (AK13 * $N$2), 1) = 0, "", CEILING(AK13 + (AK13 * $N$2), 1))*$B$3, "") | AM13: =IFERROR((AL13*AF13),"") | AN13: =IFERROR((AL13*AG13),"") | AP13: {=IFERROR(_xlfn._xlws.FILTER(#REF!,(#REF!=$C13) * (#REF!=AP$3),"" ),"")} | AQ13: {=IFERROR(_xlfn.XLOOKUP($C13,Master_Price_Level_NZ[Code],INDEX(Master_Price_Level_NZ[], , MATCH('Promo Form'!AP$3, Master_Price_Level_NZ[#Headers], 0))),"")} | AR13: =IFERROR(((AQ13*(1-AP$2))*$CN13)*AP$39,"") | AS13: =IFERROR(((AQ13*(1-AP$2))*$CN13)*AP$38,"") | AT13: =IFERROR(IF(AR13+AS13=0,"",AR13+AS13),"") | AU13: =IFERROR((($CL13/1.15)-(AQ13-(AQ13*AP$2)))/($CL13/1.15),"") | AV13: =IFERROR((($CM13/1.15)+(AR13+AS13)-(AQ13-(AQ13*AP$2)))/($CM13/1.15),"") | AW13: {=IFERROR( _xlfn.LET( _xlpm.result, INDEX(_xlfn._xlws.FILTER(ST[6wk avg], (ST[Code]=$C13)*(ST[Customer Name]=AP$3), ""), 1), IF(_xlpm.result=0, "", _xlpm.result) ), "")} | AX13: =IFERROR(IF(CEILING(AW13 + (AW13 * $N$2), 1) = 0, "", CEILING(AW13 + (AW13 * $N$2), 1))*$B$3, "") | AY13: =IFERROR((AX13*AR13),"") | AZ13: =IFERROR((AX13*AS13),"") | BB13: {=IFERROR(_xlfn._xlws.FILTER(#REF!,(#REF!=$C13) * (#REF!=BB$3),"" ),"")} | BC13: {=IFERROR(_xlfn.XLOOKUP($C13,Master_Price_Level_NZ[Code],INDEX(Master_Price_Level_NZ[], , MATCH('Promo Form'!BB$3, Master_Price_Level_NZ[#Headers], 0))),"")} | BD13: =IFERROR(((BC13*(1-BB$2))*$CN13)*BB$39,"") | BE13: =IFERROR(((BC13*(1-BB$2))*$CN13)*BB$38,"") | BF13: =IFERROR(IF(BD13+BE13=0,"",BD13+BE13),"") | BG13: =IFERROR((($CL13/1.15)-(BC13-(BC13*BB$2)))/($CL13/1.15),"") | BH13: =IFERROR((($CM13/1.15)+(BD13+BE13)-(BC13-(BC13*BB$2)))/($CM13/1.15),"") | BI13: {=IFERROR( _xlfn.LET( _xlpm.result, INDEX(_xlfn._xlws.FILTER(ST[6wk avg], (ST[Code]=$C13)*(ST[Customer Name]=BB$3), ""), 1), IF(_xlpm.result=0, "", _xlpm.result) ), "")} | BJ13: =IFERROR(IF(CEILING(BI13 + (BI13 * $N$2), 1) = 0, "", CEILING(BI13 + (BI13 * $N$2), 1))*$B$3, "") | BK13: =IFERROR((BJ13*BD13),"") | BL13: =IFERROR((BJ13*BE13),"") | BN13: {=IFERROR(_xlfn._xlws.FILTER(#REF!,(#REF!=$C13) * (#REF!=BN$3),"" ),"")} | BO13: {=IFERROR(_xlfn.XLOOKUP($C13,Master_Price_Level_NZ[Code],INDEX(Master_Price_Level_NZ[], , MATCH('Promo Form'!BN$3, Master_Price_Level_NZ[#Headers], 0))),"")} | BP13: =IFERROR(((BO13*(1-BN$2))*$CN13)*BN$39,"") | BQ13: =IFERROR(((BO13*(1-BN$2))*$CN13)*BN$38,"") | BR13: =IFERROR(IF(BP13+BQ13=0,"",BP13+BQ13),"") | BS13: =IFERROR((($CL13/1.15)-(BO13-(BO13*BN$2)))/($CL13/1.15),"") | BT13: =IFERROR((($CM13/1.15)+(BP13+BQ13)-(BO13-(BO13*BN$2)))/($CM13/1.15),"") | BU13: {=IFERROR( _xlfn.LET( _xlpm.result, INDEX(_xlfn._xlws.FILTER(ST[6wk avg], (ST[Code]=$C13)*(ST[Customer Name]=BN$3), ""), 1), IF(_xlpm.result=0, "", _xlpm.result) ), "")} | BV13: =IFERROR(IF(CEILING(BU13 + (BU13 * $N$2), 1) = 0, "", CEILING(BU13 + (BU13 * $N$2), 1))*$B$3, "") | BW13: =IFERROR((BV13*BP13),"") | BX13: =IFERROR((BV13*BQ13),"") | BZ13: {=IFERROR(_xlfn._xlws.FILTER(#REF!,(#REF!=$C13) * (#REF!=BZ$3),"" ),"")} | CA13: {=IFERROR(_xlfn.XLOOKUP($C13,Master_Price_Level_NZ[Code],INDEX(Master_Price_Level_NZ[], , MATCH('Promo Form'!BZ$3, Master_Price_Level_NZ[#Headers], 0))),"")} | CB13: =IFERROR(((CA13*(1-BZ$2))*$CN13)*BZ$39,"") | CC13: =IFERROR(((CA13*(1-BZ$2))*$CN13)*BZ$38,"") | CD13: =IFERROR(IF(CB13+CC13=0,"",CB13+CC13),"") | CE13: =IFERROR((($CL13/1.15)-(CA13-(CA13*BZ$2)))/($CL13/1.15),"") | CF13: =IFERROR((($CM13/1.15)+(CB13+CC13)-(CA13-(CA13*BZ$2)))/($CM13/1.15),"") | CG13: {=IFERROR( _xlfn.LET( _xlpm.result, INDEX(_xlfn._xlws.FILTER(ST[6wk avg], (ST[Code]=$C13)*(ST[Customer Name]=BZ$3), ""), 1), IF(_xlpm.result=0, "", _xlpm.result) ), "")} | CH13: =IFERROR(IF(CEILING(CG13 + (CG13 * $N$2), 1) = 0, "", CEILING(CG13 + (CG13 * $N$2), 1))*$B$3, "") | CI13: =IFERROR((CH13*CB13),"") | CJ13: =IFERROR((CH13*CC13),"") | CL13: =IFERROR(_xlfn.XLOOKUP(C13,Master_Price_Level_NZ[Code],Master_Price_Level_NZ[Base (RRP Inc)]),"") | CM13: =IFERROR(CL13-(CL13*CN13),"") | CN13: =IF(C13="", "",CN12) | CO13: =IFERROR((CL13-CM13),"")
